Workbook

Sheet README
A1: How this tracker works
A3: Add a task | B3: Tasks sheet, any empty row: Goal, Task, Assigned to, Status, Start (a Monday), Weeks. That's all.
A4: It then appears | B4: on the person's sheet, on its goal's sheet, on Gantt and in Dashboard. Those sheets are automatic: don't type in them.
A5: Per person | B5: One tab per person (GS-SLAM owner, Isaac Sim owner, Sensors owner, ...): their tasks and Gantt bars.
A6: Per goal | B6: One tab per goal (G1 Digital twin, G2 SCooP, Testbed, Dual-Link comm, Semantic comm).
A7: Gantt | B7: All tasks. The timeline start (Gantt!C3) sets every sheet's timeline.
A8: People | B8: Put real names in People. Then Ctrl+H in Tasks: replace each placeholder (e.g. 'GS-SLAM owner') with the name, and rename the tab.
A9: New person | B9: Add the name in People; duplicate any person tab and change its C2 to =People!A<row of the name>.
A10: Colours | B10: Bars by Status: grey Not Started, yellow In Progress, orange Partially Completed, red Blocked, green Complete; dark blue = milestone. Red End date = overdue.
A11: ID (optional) | B11: An ID without '.' shows as a bold parent row; IDs containing '-M' are milestones. New tasks can leave ID empty.
A12: Google Sheets | B12: Upload to Drive, open, File > Save as Google Sheets, share as Editor. Use only that copy.
A13: Limits | B13: Each person/goal tab lists up to 120 tasks; Tasks has room for 400 rows (Gantt shows all of them).
A15: Own file per person | B15: In Google Sheets: put names (and emails) in People, then Extensions > Apps Script, paste split_per_person.gs, run setupPersonFiles.
B16: Each person gets 'Tasks - <name>' to edit; this file's Tasks then imports everyone's rows and stays the shared overview.
B17: After that, add or edit tasks in the person's file (you own every file, so you can add tasks for anyone).

Sheet Tasks
A1: Tasks
A2: Add a task on any empty row: Goal, Task, Assigned to, Status, Start (a Monday), Weeks. It appears on that person's sheet, its goal's sheet and the Gantt by itself.
A3: ID | B3: Goal | C3: Task | D3: Assigned to | E3: Status | F3: Start | G3: Weeks | H3: End | I3: Notes | J3: key person | K3: key goal | L3: key all
A4: TB-1 | B4: Shared SCooP testbed | C4: Hardware inventory & specs | D4: Sensors & platform owner | E4: Not Started | F4: 46307 | G4: 2 | H4: =IF(OR($F4="",$G4=""),"",$F4+7*$G4-3) -> 46318 | J4: =IF(OR($C4="",$D4=""),"",$D4&"|"&COUNTIFS($D$4:$D4,$D4,$C$4:$C4,"?*")) -> Sensors & platform owner|1 | K4: =IF(OR($C4="",$B4=""),"",$B4&"|"&COUNTIFS($B$4:$B4,$B4,$C$4:$C4,"?*")) -> Shared SCooP testbed|1 | L4: =IF($C4="","","ALL|"&COUNTIF($C$4:$C4,"?*")) -> ALL|1
A5: TB-2 | B5: Shared SCooP testbed | C5: Sensor calibration (all units) | D5: Sensors & platform owner | E5: In Progress | F5: 46195 | G5: 2 | H5: =IF(OR($F5="",$G5=""),"",$F5+7*$G5-3) -> 46206 | J5: =IF(OR($C5="",$D5=""),"",$D5&"|"&COUNTIFS($D$4:$D5,$D5,$C$4:$C5,"?*")) -> Sensors & platform owner|2 | K5: =IF(OR($C5="",$B5=""),"",$B5&"|"&COUNTIFS($B$4:$B5,$B5,$C$4:$C5,"?*")) -> Shared SCooP testbed|2 | L5: =IF($C5="","","ALL|"&COUNTIF($C$4:$C5,"?*")) -> ALL|2
A6: TB-2.1 | B6: Shared SCooP testbed | C6: Sensor Calibration (LiDAR-Camera, LiDAR-IMU, Camera-Radar, Intrinsics, Realsense-Zed, Mobile-Infra Extrinsics) | D6: Sensors & platform owner | E6: In Progress | F6: 46195 | G6: 2 | H6: =IF(OR($F6="",$G6=""),"",$F6+7*$G6-3) -> 46206 | J6: =IF(OR($C6="",$D6=""),"",$D6&"|"&COUNTIFS($D$4:$D6,$D6,$C$4:$C6,"?*")) -> Sensors & platform owner|3 | K6: =IF(OR($C6="",$B6=""),"",$B6&"|"&COUNTIFS($B$4:$B6,$B6,$C$4:$C6,"?*")) -> Shared SCooP testbed|3 | L6: =IF($C6="","","ALL|"&COUNTIF($C$4:$C6,"?*")) -> ALL|3
A7: TB-2.2 | B7: Shared SCooP testbed | C7: Calibration: LiDAR - Camera | D7: Sensors & platform owner | H7: =IF(OR($F7="",$G7=""),"",$F7+7*$G7-3) | J7: =IF(OR($C7="",$D7=""),"",$D7&"|"&COUNTIFS($D$4:$D7,$D7,$C$4:$C7,"?*")) -> Sensors & platform owner|4 | K7: =IF(OR($C7="",$B7=""),"",$B7&"|"&COUNTIFS($B$4:$B7,$B7,$C$4:$C7,"?*")) -> Shared SCooP testbed|4 | L7: =IF($C7="","","ALL|"&COUNTIF($C$4:$C7,"?*")) -> ALL|4
A8: TB-2.3 | B8: Shared SCooP testbed | C8: Calibration: LiDAR - IMU | D8: Sensors & platform owner | H8: =IF(OR($F8="",$G8=""),"",$F8+7*$G8-3) | J8: =IF(OR($C8="",$D8=""),"",$D8&"|"&COUNTIFS($D$4:$D8,$D8,$C$4:$C8,"?*")) -> Sensors & platform owner|5 | K8: =IF(OR($C8="",$B8=""),"",$B8&"|"&COUNTIFS($B$4:$B8,$B8,$C$4:$C8,"?*")) -> Shared SCooP testbed|5 | L8: =IF($C8="","","ALL|"&COUNTIF($C$4:$C8,"?*")) -> ALL|5
A9: TB-2.4 | B9: Shared SCooP testbed | C9: Calibration: RealSense - ZED | D9: Sensors & platform owner | H9: =IF(OR($F9="",$G9=""),"",$F9+7*$G9-3) | J9: =IF(OR($C9="",$D9=""),"",$D9&"|"&COUNTIFS($D$4:$D9,$D9,$C$4:$C9,"?*")) -> Sensors & platform owner|6 | K9: =IF(OR($C9="",$B9=""),"",$B9&"|"&COUNTIFS($B$4:$B9,$B9,$C$4:$C9,"?*")) -> Shared SCooP testbed|6 | L9: =IF($C9="","","ALL|"&COUNTIF($C$4:$C9,"?*")) -> ALL|6
A10: TB-2.5 | B10: Shared SCooP testbed | C10: Calibration: ZED - Arducam | D10: Sensors & platform owner | H10: =IF(OR($F10="",$G10=""),"",$F10+7*$G10-3) | J10: =IF(OR($C10="",$D10=""),"",$D10&"|"&COUNTIFS($D$4:$D10,$D10,$C$4:$C10,"?*")) -> Sensors & platform owner|7 | K10: =IF(OR($C10="",$B10=""),"",$B10&"|"&COUNTIFS($B$4:$B10,$B10,$C$4:$C10,"?*")) -> Shared SCooP testbed|7 | L10: =IF($C10="","","ALL|"&COUNTIF($C$4:$C10,"?*")) -> ALL|7
A11: TB-2.6 | B11: Shared SCooP testbed | C11: Calibration: Radars - ZED | D11: Sensors & platform owner | H11: =IF(OR($F11="",$G11=""),"",$F11+7*$G11-3) | J11: =IF(OR($C11="",$D11=""),"",$D11&"|"&COUNTIFS($D$4:$D11,$D11,$C$4:$C11,"?*")) -> Sensors & platform owner|8 | K11: =IF(OR($C11="",$B11=""),"",$B11&"|"&COUNTIFS($B$4:$B11,$B11,$C$4:$C11,"?*")) -> Shared SCooP testbed|8 | L11: =IF($C11="","","ALL|"&COUNTIF($C$4:$C11,"?*")) -> ALL|8
A12: TB-3 | B12: Shared SCooP testbed | C12: Time sync & TF chain | D12: Sensors & platform owner | E12: In Progress | F12: 46202 | G12: 1 | H12: =IF(OR($F12="",$G12=""),"",$F12+7*$G12-3) -> 46206 | J12: =IF(OR($C12="",$D12=""),"",$D12&"|"&COUNTIFS($D$4:$D12,$D12,$C$4:$C12,"?*")) -> Sensors & platform owner|9 | K12: =IF(OR($C12="",$B12=""),"",$B12&"|"&COUNTIFS($B$4:$B12,$B12,$C$4:$C12,"?*")) -> Shared SCooP testbed|9 | L12: =IF($C12="","","ALL|"&COUNTIF($C$4:$C12,"?*")) -> ALL|9
A13: TB-4 | B13: Shared SCooP testbed | C13: Wi-Fi & comms logging | D13: Sensors & platform owner | E13: In Progress | F13: 46307 | G13: 2 | H13: =IF(OR($F13="",$G13=""),"",$F13+7*$G13-3) -> 46318 | J13: =IF(OR($C13="",$D13=""),"",$D13&"|"&COUNTIFS($D$4:$D13,$D13,$C$4:$C13,"?*")) -> Sensors & platform owner|10 | K13: =IF(OR($C13="",$B13=""),"",$B13&"|"&COUNTIFS($B$4:$B13,$B13,$C$4:$C13,"?*")) -> Shared SCooP testbed|10 | L13: =IF($C13="","","ALL|"&COUNTIF($C$4:$C13,"?*")) -> ALL|10
A14: TB-5 | B14: Shared SCooP testbed | C14: Recording tooling fixes | D14: Sensors & platform owner | E14: Not Started | F14: 46307 | G14: 2 | H14: =IF(OR($F14="",$G14=""),"",$F14+7*$G14-3) -> 46318 | J14: =IF(OR($C14="",$D14=""),"",$D14&"|"&COUNTIFS($D$4:$D14,$D14,$C$4:$C14,"?*")) -> Sensors & platform owner|11 | K14: =IF(OR($C14="",$B14=""),"",$B14&"|"&COUNTIFS($B$4:$B14,$B14,$C$4:$C14,"?*")) -> Shared SCooP testbed|11 | L14: =IF($C14="","","ALL|"&COUNTIF($C$4:$C14,"?*")) -> ALL|11
A15: G2-DS-1 | B15: G2 SCooP dataset & paper | C15: Recording campaign | D15: SCooP owner | E15: Partially Completed | F15: 46314 | G15: 6 | H15: =IF(OR($F15="",$G15=""),"",$F15+7*$G15-3) -> 46353 | I15: Only Cameras and LiDAR mainly for calibration accuracy validation | J15: =IF(OR($C15="",$D15=""),"",$D15&"|"&COUNTIFS($D$4:$D15,$D15,$C$4:$C15,"?*")) -> SCooP owner|1 | K15: =IF(OR($C15="",$B15=""),"",$B15&"|"&COUNTIFS($B$4:$B15,$B15,$C$4:$C15,"?*")) -> G2 SCooP dataset & paper|1 | L15: =IF($C15="","","ALL|"&COUNTIF($C$4:$C15,"?*")) -> ALL|12
A16: G2-DS-1.1 | B16: G2 SCooP dataset & paper | C16: Indoor Trajectory Sessions | D16: SCooP owner | E16: Partially Completed | F16: 46202 | G16: 1 | H16: =IF(OR($F16="",$G16=""),"",$F16+7*$G16-3) -> 46206 | I16: 2 different datasets → detect change (in validation) | J16: =IF(OR($C16="",$D16=""),"",$D16&"|"&COUNTIFS($D$4:$D16,$D16,$C$4:$C16,"?*")) -> SCooP owner|2 | K16: =IF(OR($C16="",$B16=""),"",$B16&"|"&COUNTIFS($B$4:$B16,$B16,$C$4:$C16,"?*")) -> G2 SCooP dataset & paper|2 | L16: =IF($C16="","","ALL|"&COUNTIF($C$4:$C16,"?*")) -> ALL|13
A17: G2-DS-1.2 | B17: G2 SCooP dataset & paper | C17: Outdoor Trajectory Sessions | D17: SCooP owner | E17: Not Started | H17: =IF(OR($F17="",$G17=""),"",$F17+7*$G17-3) | J17: =IF(OR($C17="",$D17=""),"",$D17&"|"&COUNTIFS($D$4:$D17,$D17,$C$4:$C17,"?*")) -> SCooP owner|3 | K17: =IF(OR($C17="",$B17=""),"",$B17&"|"&COUNTIFS($B$4:$B17,$B17,$C$4:$C17,"?*")) -> G2 SCooP dataset & paper|3 | L17: =IF($C17="","","ALL|"&COUNTIF($C$4:$C17,"?*")) -> ALL|14
A18: G2-DS-1.3 | B18: G2 SCooP dataset & paper | C18: Record sites 2 and 3 | D18: SCooP owner | E18: Not Started | F18: 46321 | G18: 4 | H18: =IF(OR($F18="",$G18=""),"",$F18+7*$G18-3) -> 46346 | J18: =IF(OR($C18="",$D18=""),"",$D18&"|"&COUNTIFS($D$4:$D18,$D18,$C$4:$C18,"?*")) -> SCooP owner|4 | K18: =IF(OR($C18="",$B18=""),"",$B18&"|"&COUNTIFS($B$4:$B18,$B18,$C$4:$C18,"?*")) -> G2 SCooP dataset & paper|4 | L18: =IF($C18="","","ALL|"&COUNTIF($C$4:$C18,"?*")) -> ALL|15
A19: G2-DS-1.4 | B19: G2 SCooP dataset & paper | C19: Calibration rosbag | D19: SCooP owner | F19: 46314 | G19: 1 | H19: =IF(OR($F19="",$G19=""),"",$F19+7*$G19-3) -> 46318 | J19: =IF(OR($C19="",$D19=""),"",$D19&"|"&COUNTIFS($D$4:$D19,$D19,$C$4:$C19,"?*")) -> SCooP owner|5 | K19: =IF(OR($C19="",$B19=""),"",$B19&"|"&COUNTIFS($B$4:$B19,$B19,$C$4:$C19,"?*")) -> G2 SCooP dataset & paper|5 | L19: =IF($C19="","","ALL|"&COUNTIF($C$4:$C19,"?*")) -> ALL|16
A20: G2-DS-1.5 | B20: G2 SCooP dataset & paper | C20: Short test recordings | D20: SCooP owner | F20: 46314 | G20: 1 | H20: =IF(OR($F20="",$G20=""),"",$F20+7*$G20-3) -> 46318 | J20: =IF(OR($C20="",$D20=""),"",$D20&"|"&COUNTIFS($D$4:$D20,$D20,$C$4:$C20,"?*")) -> SCooP owner|6 | K20: =IF(OR($C20="",$B20=""),"",$B20&"|"&COUNTIFS($B$4:$B20,$B20,$C$4:$C20,"?*")) -> G2 SCooP dataset & paper|6 | L20: =IF($C20="","","ALL|"&COUNTIF($C$4:$C20,"?*")) -> ALL|17
A21: G2-DS-2 | B21: G2 SCooP dataset & paper | C21: Per-pass processing | D21: SCooP owner | E21: In Progress | F21: 46307 | G21: 10 | H21: =IF(OR($F21="",$G21=""),"",$F21+7*$G21-3) -> 46374 | I21: rerun per new pass | J21: =IF(OR($C21="",$D21=""),"",$D21&"|"&COUNTIFS($D$4:$D21,$D21,$C$4:$C21,"?*")) -> SCooP owner|7 | K21: =IF(OR($C21="",$B21=""),"",$B21&"|"&COUNTIFS($B$4:$B21,$B21,$C$4:$C21,"?*")) -> G2 SCooP dataset & paper|7 | L21: =IF($C21="","","ALL|"&COUNTIF($C$4:$C21,"?*")) -> ALL|18
A22: G2-DS-2.1 | B22: G2 SCooP dataset & paper | C22: Merging Sensor Data | D22: SCooP owner | E22: In Progress | F22: 46202 | G22: 1 | H22: =IF(OR($F22="",$G22=""),"",$F22+7*$G22-3) -> 46206 | J22: =IF(OR($C22="",$D22=""),"",$D22&"|"&COUNTIFS($D$4:$D22,$D22,$C$4:$C22,"?*")) -> SCooP owner|8 | K22: =IF(OR($C22="",$B22=""),"",$B22&"|"&COUNTIFS($B$4:$B22,$B22,$C$4:$C22,"?*")) -> G2 SCooP dataset & paper|8 | L22: =IF($C22="","","ALL|"&COUNTIF($C$4:$C22,"?*")) -> ALL|19
A23: G2-DS-2.2 | B23: G2 SCooP dataset & paper | C23: Timestamp Alignment Post-Processing | D23: SCooP owner | E23: Not Started | F23: 46202 | G23: 1 | H23: =IF(OR($F23="",$G23=""),"",$F23+7*$G23-3) -> 46206 | J23: =IF(OR($C23="",$D23=""),"",$D23&"|"&COUNTIFS($D$4:$D23,$D23,$C$4:$C23,"?*")) -> SCooP owner|9 | K23: =IF(OR($C23="",$B23=""),"",$B23&"|"&COUNTIFS($B$4:$B23,$B23,$C$4:$C23,"?*")) -> G2 SCooP dataset & paper|9 | L23: =IF($C23="","","ALL|"&COUNTIF($C$4:$C23,"?*")) -> ALL|20
A24: G2-DS-3 | B24: G2 SCooP dataset & paper | C24: Reference maps & board networks per site | D24: SCooP owner | E24: In Progress | F24: 46307 | G24: 8 | H24: =IF(OR($F24="",$G24=""),"",$F24+7*$G24-3) -> 46360 | J24: =IF(OR($C24="",$D24=""),"",$D24&"|"&COUNTIFS($D$4:$D24,$D24,$C$4:$C24,"?*")) -> SCooP owner|10 | K24: =IF(OR($C24="",$B24=""),"",$B24&"|"&COUNTIFS($B$4:$B24,$B24,$C$4:$C24,"?*")) -> G2 SCooP dataset & paper|10 | L24: =IF($C24="","","ALL|"&COUNTIF($C$4:$C24,"?*")) -> ALL|21
A25: G2-DS-3.1 | B25: G2 SCooP dataset & paper | C25: Localization and Mapping | D25: SCooP owner | E25: Not Started | F25: 46202 | G25: 1 | H25: =IF(OR($F25="",$G25=""),"",$F25+7*$G25-3) -> 46206 | J25: =IF(OR($C25="",$D25=""),"",$D25&"|"&COUNTIFS($D$4:$D25,$D25,$C$4:$C25,"?*")) -> SCooP owner|11 | K25: =IF(OR($C25="",$B25=""),"",$B25&"|"&COUNTIFS($B$4:$B25,$B25,$C$4:$C25,"?*")) -> G2 SCooP dataset & paper|11 | L25: =IF($C25="","","ALL|"&COUNTIF($C$4:$C25,"?*")) -> ALL|22
A26: G2-DS-3.2 | B26: G2 SCooP dataset & paper | C26: Mesh Conversion | D26: SCooP owner | E26: Not Started | F26: 46209 | G26: 2 | H26: =IF(OR($F26="",$G26=""),"",$F26+7*$G26-3) -> 46220 | I26: Varying object resolution → zoom in, zoom out | J26: =IF(OR($C26="",$D26=""),"",$D26&"|"&COUNTIFS($D$4:$D26,$D26,$C$4:$C26,"?*")) -> SCooP owner|12 | K26: =IF(OR($C26="",$B26=""),"",$B26&"|"&COUNTIFS($B$4:$B26,$B26,$C$4:$C26,"?*")) -> G2 SCooP dataset & paper|12 | L26: =IF($C26="","","ALL|"&COUNTIF($C$4:$C26,"?*")) -> ALL|23
A27: G2-DS-4 | B27: G2 SCooP dataset & paper | C27: Reference poses (map stages 03-10) | D27: SCooP owner | E27: In Progress | F27: 46307 | G27: 6 | H27: =IF(OR($F27="",$G27=""),"",$F27+7*$G27-3) -> 46346 | J27: =IF(OR($C27="",$D27=""),"",$D27&"|"&COUNTIFS($D$4:$D27,$D27,$C$4:$C27,"?*")) -> SCooP owner|13 | K27: =IF(OR($C27="",$B27=""),"",$B27&"|"&COUNTIFS($B$4:$B27,$B27,$C$4:$C27,"?*")) -> G2 SCooP dataset & paper|13 | L27: =IF($C27="","","ALL|"&COUNTIF($C$4:$C27,"?*")) -> ALL|24
A28: G2-DS-5 | B28: G2 SCooP dataset & paper | C28: Ground-truth validation | D28: SCooP owner | E28: Not Started | F28: 46342 | G28: 3 | H28: =IF(OR($F28="",$G28=""),"",$F28+7*$G28-3) -> 46360 | J28: =IF(OR($C28="",$D28=""),"",$D28&"|"&COUNTIFS($D$4:$D28,$D28,$C$4:$C28,"?*")) -> SCooP owner|14 | K28: =IF(OR($C28="",$B28=""),"",$B28&"|"&COUNTIFS($B$4:$B28,$B28,$C$4:$C28,"?*")) -> G2 SCooP dataset & paper|14 | L28: =IF($C28="","","ALL|"&COUNTIF($C$4:$C28,"?*")) -> ALL|25
A29: G2-DS-6 | B29: G2 SCooP dataset & paper | C29: Annotations | D29: SCooP owner | E29: Not Started | F29: 46335 | G29: 7 | H29: =IF(OR($F29="",$G29=""),"",$F29+7*$G29-3) -> 46381 | J29: =IF(OR($C29="",$D29=""),"",$D29&"|"&COUNTIFS($D$4:$D29,$D29,$C$4:$C29,"?*")) -> SCooP owner|15 | K29: =IF(OR($C29="",$B29=""),"",$B29&"|"&COUNTIFS($B$4:$B29,$B29,$C$4:$C29,"?*")) -> G2 SCooP dataset & paper|15 | L29: =IF($C29="","","ALL|"&COUNTIF($C$4:$C29,"?*")) -> ALL|26
A30: G2-DS-6.1 | B30: G2 SCooP dataset & paper | C30: Label QA (Coverage & Class Balance) | D30: SCooP owner | E30: Not Started | H30: =IF(OR($F30="",$G30=""),"",$F30+7*$G30-3) | J30: =IF(OR($C30="",$D30=""),"",$D30&"|"&COUNTIFS($D$4:$D30,$D30,$C$4:$C30,"?*")) -> SCooP owner|16 | K30: =IF(OR($C30="",$B30=""),"",$B30&"|"&COUNTIFS($B$4:$B30,$B30,$C$4:$C30,"?*")) -> G2 SCooP dataset & paper|16 | L30: =IF($C30="","","ALL|"&COUNTIF($C$4:$C30,"?*")) -> ALL|27
A31: G2-DS-7 | B31: G2 SCooP dataset & paper | C31: Collaboration geometry & comm ground truth | D31: SCooP owner | E31: Not Started | F31: 46349 | G31: 5 | H31: =IF(OR($F31="",$G31=""),"",$F31+7*$G31-3) -> 46381 | J31: =IF(OR($C31="",$D31=""),"",$D31&"|"&COUNTIFS($D$4:$D31,$D31,$C$4:$C31,"?*")) -> SCooP owner|17 | K31: =IF(OR($C31="",$B31=""),"",$B31&"|"&COUNTIFS($B$4:$B31,$B31,$C$4:$C31,"?*")) -> G2 SCooP dataset & paper|17 | L31: =IF($C31="","","ALL|"&COUNTIF($C$4:$C31,"?*")) -> ALL|28
A32: G2-DS-8 | B32: G2 SCooP dataset & paper | C32: Release | D32: SCooP owner | E32: Not Started | F32: 46384 | G32: 5 | H32: =IF(OR($F32="",$G32=""),"",$F32+7*$G32-3) -> 46416 | J32: =IF(OR($C32="",$D32=""),"",$D32&"|"&COUNTIFS($D$4:$D32,$D32,$C$4:$C32,"?*")) -> SCooP owner|18 | K32: =IF(OR($C32="",$B32=""),"",$B32&"|"&COUNTIFS($B$4:$B32,$B32,$C$4:$C32,"?*")) -> G2 SCooP dataset & paper|18 | L32: =IF($C32="","","ALL|"&COUNTIF($C$4:$C32,"?*")) -> ALL|29
A33: G2-DS-8.1 | B33: G2 SCooP dataset & paper | C33: Dataset Packaging & Documentation | D33: SCooP owner | E33: Not Started | H33: =IF(OR($F33="",$G33=""),"",$F33+7*$G33-3) | J33: =IF(OR($C33="",$D33=""),"",$D33&"|"&COUNTIFS($D$4:$D33,$D33,$C$4:$C33,"?*")) -> SCooP owner|19 | K33: =IF(OR($C33="",$B33=""),"",$B33&"|"&COUNTIFS($B$4:$B33,$B33,$C$4:$C33,"?*")) -> G2 SCooP dataset & paper|19 | L33: =IF($C33="","","ALL|"&COUNTIF($C$4:$C33,"?*")) -> ALL|30
A34: G2-DS-8.2 | B34: G2 SCooP dataset & paper | C34: Devkit | D34: SCooP owner | E34: Not Started | F34: 46384 | G34: 4 | H34: =IF(OR($F34="",$G34=""),"",$F34+7*$G34-3) -> 46409 | J34: =IF(OR($C34="",$D34=""),"",$D34&"|"&COUNTIFS($D$4:$D34,$D34,$C$4:$C34,"?*")) -> SCooP owner|20 | K34: =IF(OR($C34="",$B34=""),"",$B34&"|"&COUNTIFS($B$4:$B34,$B34,$C$4:$C34,"?*")) -> G2 SCooP dataset & paper|20 | L34: =IF($C34="","","ALL|"&COUNTIF($C$4:$C34,"?*")) -> ALL|31
A35: G2-DS-8.3 | B35: G2 SCooP dataset & paper | C35: License, DOI, hosting | D35: SCooP owner | E35: Not Started | F35: 46398 | G35: 2 | H35: =IF(OR($F35="",$G35=""),"",$F35+7*$G35-3) -> 46409 | J35: =IF(OR($C35="",$D35=""),"",$D35&"|"&COUNTIFS($D$4:$D35,$D35,$C$4:$C35,"?*")) -> SCooP owner|21 | K35: =IF(OR($C35="",$B35=""),"",$B35&"|"&COUNTIFS($B$4:$B35,$B35,$C$4:$C35,"?*")) -> G2 SCooP dataset & paper|21 | L35: =IF($C35="","","ALL|"&COUNTIF($C$4:$C35,"?*")) -> ALL|32
A36: G2-BP-A | B36: G2 SCooP dataset & paper | C36: Ground-truth numbers (RESULTS_PLAN A0) | D36: SCooP owner | E36: Not Started | F36: 46314 | G36: 3 | H36: =IF(OR($F36="",$G36=""),"",$F36+7*$G36-3) -> 46332 | J36: =IF(OR($C36="",$D36=""),"",$D36&"|"&COUNTIFS($D$4:$D36,$D36,$C$4:$C36,"?*")) -> SCooP owner|22 | K36: =IF(OR($C36="",$B36=""),"",$B36&"|"&COUNTIFS($B$4:$B36,$B36,$C$4:$C36,"?*")) -> G2 SCooP dataset & paper|22 | L36: =IF($C36="","","ALL|"&COUNTIF($C$4:$C36,"?*")) -> ALL|33
A37: G2-BP-B | B37: G2 SCooP dataset & paper | C37: Inventory & statistics tables (B) | D37: SCooP owner | E37: Not Started | F37: 46342 | G37: 3 | H37: =IF(OR($F37="",$G37=""),"",$F37+7*$G37-3) -> 46360 | J37: =IF(OR($C37="",$D37=""),"",$D37&"|"&COUNTIFS($D$4:$D37,$D37,$C$4:$C37,"?*")) -> SCooP owner|23 | K37: =IF(OR($C37="",$B37=""),"",$B37&"|"&COUNTIFS($B$4:$B37,$B37,$C$4:$C37,"?*")) -> G2 SCooP dataset & paper|23 | L37: =IF($C37="","","ALL|"&COUNTIF($C$4:$C37,"?*")) -> ALL|34
A38: G2-BP-C | B38: G2 SCooP dataset & paper | C38: Geometry validation (C) | D38: SCooP owner | E38: Not Started | F38: 46363 | G38: 3 | H38: =IF(OR($F38="",$G38=""),"",$F38+7*$G38-3) -> 46381 | J38: =IF(OR($C38="",$D38=""),"",$D38&"|"&COUNTIFS($D$4:$D38,$D38,$C$4:$C38,"?*")) -> SCooP owner|24 | K38: =IF(OR($C38="",$B38=""),"",$B38&"|"&COUNTIFS($B$4:$B38,$B38,$C$4:$C38,"?*")) -> G2 SCooP dataset & paper|24 | L38: =IF($C38="","","ALL|"&COUNTIF($C$4:$C38,"?*")) -> ALL|35
A39: G2-BP-D | B39: G2 SCooP dataset & paper | C39: T2 collaborative perception under 3 channels (D) | D39: SCooP owner | E39: Not Started | F39: 46363 | G39: 5 | H39: =IF(OR($F39="",$G39=""),"",$F39+7*$G39-3) -> 46395 | J39: =IF(OR($C39="",$D39=""),"",$D39&"|"&COUNTIFS($D$4:$D39,$D39,$C$4:$C39,"?*")) -> SCooP owner|25 | K39: =IF(OR($C39="",$B39=""),"",$B39&"|"&COUNTIFS($B$4:$B39,$B39,$C$4:$C39,"?*")) -> G2 SCooP dataset & paper|25 | L39: =IF($C39="","","ALL|"&COUNTIF($C$4:$C39,"?*")) -> ALL|36
A40: G2-BP-E | B40: G2 SCooP dataset & paper | C40: T1 collaborative SLAM (E) | D40: SCooP owner | E40: Not Started | F40: 46363 | G40: 5 | H40: =IF(OR($F40="",$G40=""),"",$F40+7*$G40-3) -> 46395 | J40: =IF(OR($C40="",$D40=""),"",$D40&"|"&COUNTIFS($D$4:$D40,$D40,$C$4:$C40,"?*")) -> SCooP owner|26 | K40: =IF(OR($C40="",$B40=""),"",$B40&"|"&COUNTIFS($B$4:$B40,$B40,$C$4:$C40,"?*")) -> G2 SCooP dataset & paper|26 | L40: =IF($C40="","","ALL|"&COUNTIF($C$4:$C40,"?*")) -> ALL|37
...

Sheet Dashboard
A1: Dashboard
A2: Counts from Tasks. Nothing to edit.
A4: Goal | B4: Not Started | C4: In Progress | D4: Blocked | E4: Complete | F4: Partially Completed | G4: No status | H4: Total | I4: Overdue
A5: G1 ED305 live digital twin | B5: =COUNTIFS(Tasks!$B$4:$B$403,$A5,Tasks!$C$4:$C$403,"?*",Tasks!$E$4:$E$403,"Not Started") -> 41 | C5: =COUNTIFS(Tasks!$B$4:$B$403,$A5,Tasks!$C$4:$C$403,"?*",Tasks!$E$4:$E$403,"In Progress") -> 1 | D5: =COUNTIFS(Tasks!$B$4:$B$403,$A5,Tasks!$C$4:$C$403,"?*",Tasks!$E$4:$E$403,"Blocked") -> 1 | E5: =COUNTIFS(Tasks!$B$4:$B$403,$A5,Tasks!$C$4:$C$403,"?*",Tasks!$E$4:$E$403,"Complete") -> 0 | F5: =COUNTIFS(Tasks!$B$4:$B$403,$A5,Tasks!$C$4:$C$403,"?*",Tasks!$E$4:$E$403,"Partially Completed") -> 0 | G5: =COUNTIFS(Tasks!$B$4:$B$403,$A5,Tasks!$C$4:$C$403,"?*",Tasks!$E$4:$E$403,"") -> 0 | H5: =SUM(B5:G5) -> 43 | I5: =COUNTIFS(Tasks!$B$4:$B$403,$A5,Tasks!$C$4:$C$403,"?*",Tasks!$H$4:$H$403,"<"&TODAY(),Tasks!$E$4:$E$403,"<>Complete") -> 6
A6: G2 SCooP dataset & paper | B6: =COUNTIFS(Tasks!$B$4:$B$403,$A6,Tasks!$C$4:$C$403,"?*",Tasks!$E$4:$E$403,"Not Started") -> 21 | C6: =COUNTIFS(Tasks!$B$4:$B$403,$A6,Tasks!$C$4:$C$403,"?*",Tasks!$E$4:$E$403,"In Progress") -> 4 | D6: =COUNTIFS(Tasks!$B$4:$B$403,$A6,Tasks!$C$4:$C$403,"?*",Tasks!$E$4:$E$403,"Blocked") -> 0 | E6: =COUNTIFS(Tasks!$B$4:$B$403,$A6,Tasks!$C$4:$C$403,"?*",Tasks!$E$4:$E$403,"Complete") -> 0 | F6: =COUNTIFS(Tasks!$B$4:$B$403,$A6,Tasks!$C$4:$C$403,"?*",Tasks!$E$4:$E$403,"Partially Completed") -> 2 | G6: =COUNTIFS(Tasks!$B$4:$B$403,$A6,Tasks!$C$4:$C$403,"?*",Tasks!$E$4:$E$403,"") -> 2 | H6: =SUM(B6:G6) -> 29 | I6: =COUNTIFS(Tasks!$B$4:$B$403,$A6,Tasks!$C$4:$C$403,"?*",Tasks!$H$4:$H$403,"<"&TODAY(),Tasks!$E$4:$E$403,"<>Complete") -> 5
A7: Shared SCooP testbed | B7: =COUNTIFS(Tasks!$B$4:$B$403,$A7,Tasks!$C$4:$C$403,"?*",Tasks!$E$4:$E$403,"Not Started") -> 2 | C7: =COUNTIFS(Tasks!$B$4:$B$403,$A7,Tasks!$C$4:$C$403,"?*",Tasks!$E$4:$E$403,"In Progress") -> 4 | D7: =COUNTIFS(Tasks!$B$4:$B$403,$A7,Tasks!$C$4:$C$403,"?*",Tasks!$E$4:$E$403,"Blocked") -> 0 | E7: =COUNTIFS(Tasks!$B$4:$B$403,$A7,Tasks!$C$4:$C$403,"?*",Tasks!$E$4:$E$403,"Complete") -> 0 | F7: =COUNTIFS(Tasks!$B$4:$B$403,$A7,Tasks!$C$4:$C$403,"?*",Tasks!$E$4:$E$403,"Partially Completed") -> 0 | G7: =COUNTIFS(Tasks!$B$4:$B$403,$A7,Tasks!$C$4:$C$403,"?*",Tasks!$E$4:$E$403,"") -> 5 | H7: =SUM(B7:G7) -> 11 | I7: =COUNTIFS(Tasks!$B$4:$B$403,$A7,Tasks!$C$4:$C$403,"?*",Tasks!$H$4:$H$403,"<"&TODAY(),Tasks!$E$4:$E$403,"<>Complete") -> 3
A8: Dual-Link Communication | B8: =COUNTIFS(Tasks!$B$4:$B$403,$A8,Tasks!$C$4:$C$403,"?*",Tasks!$E$4:$E$403,"Not Started") -> 13 | C8: =COUNTIFS(Tasks!$B$4:$B$403,$A8,Tasks!$C$4:$C$403,"?*",Tasks!$E$4:$E$403,"In Progress") -> 2 | D8: =COUNTIFS(Tasks!$B$4:$B$403,$A8,Tasks!$C$4:$C$403,"?*",Tasks!$E$4:$E$403,"Blocked") -> 0 | E8: =COUNTIFS(Tasks!$B$4:$B$403,$A8,Tasks!$C$4:$C$403,"?*",Tasks!$E$4:$E$403,"Complete") -> 0 | F8: =COUNTIFS(Tasks!$B$4:$B$403,$A8,Tasks!$C$4:$C$403,"?*",Tasks!$E$4:$E$403,"Partially Completed") -> 7 | G8: =COUNTIFS(Tasks!$B$4:$B$403,$A8,Tasks!$C$4:$C$403,"?*",Tasks!$E$4:$E$403,"") -> 0 | H8: =SUM(B8:G8) -> 22 | I8: =COUNTIFS(Tasks!$B$4:$B$403,$A8,Tasks!$C$4:$C$403,"?*",Tasks!$H$4:$H$403,"<"&TODAY(),Tasks!$E$4:$E$403,"<>Complete") -> 22
A9: Semantic Communication | B9: =COUNTIFS(Tasks!$B$4:$B$403,$A9,Tasks!$C$4:$C$403,"?*",Tasks!$E$4:$E$403,"Not Started") -> 14 | C9: =COUNTIFS(Tasks!$B$4:$B$403,$A9,Tasks!$C$4:$C$403,"?*",Tasks!$E$4:$E$403,"In Progress") -> 0 | D9: =COUNTIFS(Tasks!$B$4:$B$403,$A9,Tasks!$C$4:$C$403,"?*",Tasks!$E$4:$E$403,"Blocked") -> 0 | E9: =COUNTIFS(Tasks!$B$4:$B$403,$A9,Tasks!$C$4:$C$403,"?*",Tasks!$E$4:$E$403,"Complete") -> 0 | F9: =COUNTIFS(Tasks!$B$4:$B$403,$A9,Tasks!$C$4:$C$403,"?*",Tasks!$E$4:$E$403,"Partially Completed") -> 0 | G9: =COUNTIFS(Tasks!$B$4:$B$403,$A9,Tasks!$C$4:$C$403,"?*",Tasks!$E$4:$E$403,"") -> 0 | H9: =SUM(B9:G9) -> 14 | I9: =COUNTIFS(Tasks!$B$4:$B$403,$A9,Tasks!$C$4:$C$403,"?*",Tasks!$H$4:$H$403,"<"&TODAY(),Tasks!$E$4:$E$403,"<>Complete") -> 6
A10: Total | B10: =SUM(B5:B9) -> 91 | C10: =SUM(C5:C9) -> 11 | D10: =SUM(D5:D9) -> 1 | E10: =SUM(E5:E9) -> 0 | F10: =SUM(F5:F9) -> 9 | G10: =SUM(G5:G9) -> 7 | H10: =SUM(H5:H9) -> 119 | I10: =SUM(I5:I9) -> 42
A13: Person | B13: Not Started | C13: In Progress | D13: Blocked | E13: Complete | F13: Partially Completed | G13: No status | H13: Total | I13: Overdue
A14: =People!$A$4 -> GS-SLAM owner | B14: =COUNTIFS(Tasks!$D$4:$D$403,$A14,Tasks!$C$4:$C$403,"?*",Tasks!$E$4:$E$403,"Not Started") -> 8 | C14: =COUNTIFS(Tasks!$D$4:$D$403,$A14,Tasks!$C$4:$C$403,"?*",Tasks!$E$4:$E$403,"In Progress") -> 0 | D14: =COUNTIFS(Tasks!$D$4:$D$403,$A14,Tasks!$C$4:$C$403,"?*",Tasks!$E$4:$E$403,"Blocked") -> 0 | E14: =COUNTIFS(Tasks!$D$4:$D$403,$A14,Tasks!$C$4:$C$403,"?*",Tasks!$E$4:$E$403,"Complete") -> 0 | F14: =COUNTIFS(Tasks!$D$4:$D$403,$A14,Tasks!$C$4:$C$403,"?*",Tasks!$E$4:$E$403,"Partially Completed") -> 0 | G14: =COUNTIFS(Tasks!$D$4:$D$403,$A14,Tasks!$C$4:$C$403,"?*",Tasks!$E$4:$E$403,"") -> 0 | H14: =SUM(B14:G14) -> 8 | I14: =COUNTIFS(Tasks!$D$4:$D$403,$A14,Tasks!$C$4:$C$403,"?*",Tasks!$H$4:$H$403,"<"&TODAY(),Tasks!$E$4:$E$403,"<>Complete") -> 2
A15: =People!$A$5 -> Isaac Sim owner | B15: =COUNTIFS(Tasks!$D$4:$D$403,$A15,Tasks!$C$4:$C$403,"?*",Tasks!$E$4:$E$403,"Not Started") -> 8 | C15: =COUNTIFS(Tasks!$D$4:$D$403,$A15,Tasks!$C$4:$C$403,"?*",Tasks!$E$4:$E$403,"In Progress") -> 0 | D15: =COUNTIFS(Tasks!$D$4:$D$403,$A15,Tasks!$C$4:$C$403,"?*",Tasks!$E$4:$E$403,"Blocked") -> 0 | E15: =COUNTIFS(Tasks!$D$4:$D$403,$A15,Tasks!$C$4:$C$403,"?*",Tasks!$E$4:$E$403,"Complete") -> 0 | F15: =COUNTIFS(Tasks!$D$4:$D$403,$A15,Tasks!$C$4:$C$403,"?*",Tasks!$E$4:$E$403,"Partially Completed") -> 0 | G15: =COUNTIFS(Tasks!$D$4:$D$403,$A15,Tasks!$C$4:$C$403,"?*",Tasks!$E$4:$E$403,"") -> 0 | H15: =SUM(B15:G15) -> 8 | I15: =COUNTIFS(Tasks!$D$4:$D$403,$A15,Tasks!$C$4:$C$403,"?*",Tasks!$H$4:$H$403,"<"&TODAY(),Tasks!$E$4:$E$403,"<>Complete") -> 0
A16: =People!$A$6 -> Sensors & platform owner | B16: =COUNTIFS(Tasks!$D$4:$D$403,$A16,Tasks!$C$4:$C$403,"?*",Tasks!$E$4:$E$403,"Not Started") -> 6 | C16: =COUNTIFS(Tasks!$D$4:$D$403,$A16,Tasks!$C$4:$C$403,"?*",Tasks!$E$4:$E$403,"In Progress") -> 5 | D16: =COUNTIFS(Tasks!$D$4:$D$403,$A16,Tasks!$C$4:$C$403,"?*",Tasks!$E$4:$E$403,"Blocked") -> 1 | E16: =COUNTIFS(Tasks!$D$4:$D$403,$A16,Tasks!$C$4:$C$403,"?*",Tasks!$E$4:$E$403,"Complete") -> 0 | F16: =COUNTIFS(Tasks!$D$4:$D$403,$A16,Tasks!$C$4:$C$403,"?*",Tasks!$E$4:$E$403,"Partially Completed") -> 0 | G16: =COUNTIFS(Tasks!$D$4:$D$403,$A16,Tasks!$C$4:$C$403,"?*",Tasks!$E$4:$E$403,"") -> 5 | H16: =SUM(B16:G16) -> 17 | I16: =COUNTIFS(Tasks!$D$4:$D$403,$A16,Tasks!$C$4:$C$403,"?*",Tasks!$H$4:$H$403,"<"&TODAY(),Tasks!$E$4:$E$403,"<>Complete") -> 3
A17: =People!$A$7 -> Scene detection owner | B17: =COUNTIFS(Tasks!$D$4:$D$403,$A17,Tasks!$C$4:$C$403,"?*",Tasks!$E$4:$E$403,"Not Started") -> 11 | C17: =COUNTIFS(Tasks!$D$4:$D$403,$A17,Tasks!$C$4:$C$403,"?*",Tasks!$E$4:$E$403,"In Progress") -> 0 | D17: =COUNTIFS(Tasks!$D$4:$D$403,$A17,Tasks!$C$4:$C$403,"?*",Tasks!$E$4:$E$403,"Blocked") -> 0 | E17: =COUNTIFS(Tasks!$D$4:$D$403,$A17,Tasks!$C$4:$C$403,"?*",Tasks!$E$4:$E$403,"Complete") -> 0 | F17: =COUNTIFS(Tasks!$D$4:$D$403,$A17,Tasks!$C$4:$C$403,"?*",Tasks!$E$4:$E$403,"Partially Completed") -> 0 | G17: =COUNTIFS(Tasks!$D$4:$D$403,$A17,Tasks!$C$4:$C$403,"?*",Tasks!$E$4:$E$403,"") -> 0 | H17: =SUM(B17:G17) -> 11 | I17: =COUNTIFS(Tasks!$D$4:$D$403,$A17,Tasks!$C$4:$C$403,"?*",Tasks!$H$4:$H$403,"<"&TODAY(),Tasks!$E$4:$E$403,"<>Complete") -> 4
A18: =People!$A$8 -> Sionna RT owner | B18: =COUNTIFS(Tasks!$D$4:$D$403,$A18,Tasks!$C$4:$C$403,"?*",Tasks!$E$4:$E$403,"Not Started") -> 4 | C18: =COUNTIFS(Tasks!$D$4:$D$403,$A18,Tasks!$C$4:$C$403,"?*",Tasks!$E$4:$E$403,"In Progress") -> 0 | D18: =COUNTIFS(Tasks!$D$4:$D$403,$A18,Tasks!$C$4:$C$403,"?*",Tasks!$E$4:$E$403,"Blocked") -> 0 | E18: =COUNTIFS(Tasks!$D$4:$D$403,$A18,Tasks!$C$4:$C$403,"?*",Tasks!$E$4:$E$403,"Complete") -> 0 | F18: =COUNTIFS(Tasks!$D$4:$D$403,$A18,Tasks!$C$4:$C$403,"?*",Tasks!$E$4:$E$403,"Partially Completed") -> 0 | G18: =COUNTIFS(Tasks!$D$4:$D$403,$A18,Tasks!$C$4:$C$403,"?*",Tasks!$E$4:$E$403,"") -> 0 | H18: =SUM(B18:G18) -> 4 | I18: =COUNTIFS(Tasks!$D$4:$D$403,$A18,Tasks!$C$4:$C$403,"?*",Tasks!$H$4:$H$403,"<"&TODAY(),Tasks!$E$4:$E$403,"<>Complete") -> 0
A19: =People!$A$9 -> SCooP owner | B19: =COUNTIFS(Tasks!$D$4:$D$403,$A19,Tasks!$C$4:$C$403,"?*",Tasks!$E$4:$E$403,"Not Started") -> 21 | C19: =COUNTIFS(Tasks!$D$4:$D$403,$A19,Tasks!$C$4:$C$403,"?*",Tasks!$E$4:$E$403,"In Progress") -> 4 | D19: =COUNTIFS(Tasks!$D$4:$D$403,$A19,Tasks!$C$4:$C$403,"?*",Tasks!$E$4:$E$403,"Blocked") -> 0 | E19: =COUNTIFS(Tasks!$D$4:$D$403,$A19,Tasks!$C$4:$C$403,"?*",Tasks!$E$4:$E$403,"Complete") -> 0 | F19: =COUNTIFS(Tasks!$D$4:$D$403,$A19,Tasks!$C$4:$C$403,"?*",Tasks!$E$4:$E$403,"Partially Completed") -> 2 | G19: =COUNTIFS(Tasks!$D$4:$D$403,$A19,Tasks!$C$4:$C$403,"?*",Tasks!$E$4:$E$403,"") -> 2 | H19: =SUM(B19:G19) -> 29 | I19: =COUNTIFS(Tasks!$D$4:$D$403,$A19,Tasks!$C$4:$C$403,"?*",Tasks!$H$4:$H$403,"<"&TODAY(),Tasks!$E$4:$E$403,"<>Complete") -> 5
A20: =People!$A$10 -> Dual-link owner | B20: =COUNTIFS(Tasks!$D$4:$D$403,$A20,Tasks!$C$4:$C$403,"?*",Tasks!$E$4:$E$403,"Not Started") -> 13 | C20: =COUNTIFS(Tasks!$D$4:$D$403,$A20,Tasks!$C$4:$C$403,"?*",Tasks!$E$4:$E$403,"In Progress") -> 2 | D20: =COUNTIFS(Tasks!$D$4:$D$403,$A20,Tasks!$C$4:$C$403,"?*",Tasks!$E$4:$E$403,"Blocked") -> 0 | E20: =COUNTIFS(Tasks!$D$4:$D$403,$A20,Tasks!$C$4:$C$403,"?*",Tasks!$E$4:$E$403,"Complete") -> 0 | F20: =COUNTIFS(Tasks!$D$4:$D$403,$A20,Tasks!$C$4:$C$403,"?*",Tasks!$E$4:$E$403,"Partially Completed") -> 7 | G20: =COUNTIFS(Tasks!$D$4:$D$403,$A20,Tasks!$C$4:$C$403,"?*",Tasks!$E$4:$E$403,"") -> 0 | H20: =SUM(B20:G20) -> 22 | I20: =COUNTIFS(Tasks!$D$4:$D$403,$A20,Tasks!$C$4:$C$403,"?*",Tasks!$H$4:$H$403,"<"&TODAY(),Tasks!$E$4:$E$403,"<>Complete") -> 22
A21: =People!$A$11 -> Semantic comm owner | B21: =COUNTIFS(Tasks!$D$4:$D$403,$A21,Tasks!$C$4:$C$403,"?*",Tasks!$E$4:$E$403,"Not Started") -> 14 | C21: =COUNTIFS(Tasks!$D$4:$D$403,$A21,Tasks!$C$4:$C$403,"?*",Tasks!$E$4:$E$403,"In Progress") -> 0 | D21: =COUNTIFS(Tasks!$D$4:$D$403,$A21,Tasks!$C$4:$C$403,"?*",Tasks!$E$4:$E$403,"Blocked") -> 0 | E21: =COUNTIFS(Tasks!$D$4:$D$403,$A21,Tasks!$C$4:$C$403,"?*",Tasks!$E$4:$E$403,"Complete") -> 0 | F21: =COUNTIFS(Tasks!$D$4:$D$403,$A21,Tasks!$C$4:$C$403,"?*",Tasks!$E$4:$E$403,"Partially Completed") -> 0 | G21: =COUNTIFS(Tasks!$D$4:$D$403,$A21,Tasks!$C$4:$C$403,"?*",Tasks!$E$4:$E$403,"") -> 0 | H21: =SUM(B21:G21) -> 14 | I21: =COUNTIFS(Tasks!$D$4:$D$403,$A21,Tasks!$C$4:$C$403,"?*",Tasks!$H$4:$H$403,"<"&TODAY(),Tasks!$E$4:$E$403,"<>Complete") -> 6
A22: =People!$A$12 -> Team | B22: =COUNTIFS(Tasks!$D$4:$D$403,$A22,Tasks!$C$4:$C$403,"?*",Tasks!$E$4:$E$403,"Not Started") -> 6 | C22: =COUNTIFS(Tasks!$D$4:$D$403,$A22,Tasks!$C$4:$C$403,"?*",Tasks!$E$4:$E$403,"In Progress") -> 0 | D22: =COUNTIFS(Tasks!$D$4:$D$403,$A22,Tasks!$C$4:$C$403,"?*",Tasks!$E$4:$E$403,"Blocked") -> 0 | E22: =COUNTIFS(Tasks!$D$4:$D$403,$A22,Tasks!$C$4:$C$403,"?*",Tasks!$E$4:$E$403,"Complete") -> 0 | F22: =COUNTIFS(Tasks!$D$4:$D$403,$A22,Tasks!$C$4:$C$403,"?*",Tasks!$E$4:$E$403,"Partially Completed") -> 0 | G22: =COUNTIFS(Tasks!$D$4:$D$403,$A22,Tasks!$C$4:$C$403,"?*",Tasks!$E$4:$E$403,"") -> 0 | H22: =SUM(B22:G22) -> 6 | I22: =COUNTIFS(Tasks!$D$4:$D$403,$A22,Tasks!$C$4:$C$403,"?*",Tasks!$H$4:$H$403,"<"&TODAY(),Tasks!$E$4:$E$403,"<>Complete") -> 0
A23: Total | B23: =SUM(B14:B22) -> 91 | C23: =SUM(C14:C22) -> 11 | D23: =SUM(D14:D22) -> 1 | E23: =SUM(E14:E22) -> 0 | F23: =SUM(F14:F22) -> 9 | G23: =SUM(G14:G22) -> 7 | H23: =SUM(H14:H22) -> 119 | I23: =SUM(I14:I22) -> 42

Sheet Gantt
B1: Gantt: all tasks
C2: ALL | E2: =COUNTIF(Tasks!$C$4:$C$403,"?*")&" tasks · "&COUNTIFS(Tasks!$H$4:$H$403,"<"&TODAY(),Tasks!$E$4:$E$403,"<>Complete")&" overdue" -> 119 tasks · 42 overdue
B3: Gantt starts (Monday): | C3: 46195
A4: Tasks row | B4: ID | C4: Task | D4: Assigned to | E4: Status | F4: Start | G4: End | H4: =$C$3+7*0 -> 46195 | I4: =$C$3+7*1 -> 46202 | J4: =$C$3+7*2 -> 46209 | K4: =$C$3+7*3 -> 46216 | L4: =$C$3+7*4 -> 46223 | M4: =$C$3+7*5 -> 46230 | N4: =$C$3+7*6 -> 46237 | O4: =$C$3+7*7 -> 46244 | P4: =$C$3+7*8 -> 46251 | Q4: =$C$3+7*9 -> 46258 | R4: =$C$3+7*10 -> 46265 | S4: =$C$3+7*11 -> 46272 | T4: =$C$3+7*12 -> 46279 | U4: =$C$3+7*13 -> 46286 | V4: =$C$3+7*14 -> 46293 | W4: =$C$3+7*15 -> 46300 | X4: =$C$3+7*16 -> 46307 | Y4: =$C$3+7*17 -> 46314 | Z4: =$C$3+7*18 -> 46321 | AA4: =$C$3+7*19 -> 46328 | AB4: =$C$3+7*20 -> 46335 | AC4: =$C$3+7*21 -> 46342 | AD4: =$C$3+7*22 -> 46349 | AE4: =$C$3+7*23 -> 46356 | AF4: =$C$3+7*24 -> 46363 | AG4: =$C$3+7*25 -> 46370 | AH4: =$C$3+7*26 -> 46377 | AI4: =$C$3+7*27 -> 46384 | AJ4: =$C$3+7*28 -> 46391 | AK4: =$C$3+7*29 -> 46398 | AL4: =$C$3+7*30 -> 46405 | AM4: =$C$3+7*31 -> 46412 | AN4: =$C$3+7*32 -> 46419 | AO4: =$C$3+7*33 -> 46426 | AP4: =$C$3+7*34 -> 46433 | AQ4: =$C$3+7*35 -> 46440 | AR4: =$C$3+7*36 -> 46447 | AS4: =$C$3+7*37 -> 46454 | AT4: =$C$3+7*38 -> 46461 | AU4: =$C$3+7*39 -> 46468 | AV4: =$C$3+7*40 -> 46475 | AW4: =$C$3+7*41 -> 46482 | AX4: =$C$3+7*42 -> 46489 | AY4: =$C$3+7*43 -> 46496 | BB4: Legend
A5: =IFERROR(MATCH($C$2&"|"&(ROW()-4),Tasks!$L$4:$L$403,0)+3,"") -> 4 | B5: =IF($A5="","",IF(INDEX(Tasks!$A:$A,$A5)="","",INDEX(Tasks!$A:$A,$A5))) -> TB-1 | C5: =IF($A5="","",IF(ISERROR(FIND(".",INDEX(Tasks!$A:$A,$A5))),""," ")&INDEX(Tasks!$C:$C,$A5)) -> Hardware inventory & specs | D5: =IF($A5="","",IF(INDEX(Tasks!$D:$D,$A5)="","",INDEX(Tasks!$D:$D,$A5))) -> Sensors & platform owner | E5: =IF($A5="","",IF(INDEX(Tasks!$E:$E,$A5)="","",INDEX(Tasks!$E:$E,$A5))) -> Not Started | F5: =IF($A5="","",IF(INDEX(Tasks!$F:$F,$A5)="","",INDEX(Tasks!$F:$F,$A5))) -> 46307 | G5: =IF($A5="","",IF(INDEX(Tasks!$H:$H,$A5)="","",INDEX(Tasks!$H:$H,$A5))) -> 46318 | BB5: Complete
A6: =IFERROR(MATCH($C$2&"|"&(ROW()-4),Tasks!$L$4:$L$403,0)+3,"") -> 5 | B6: =IF($A6="","",IF(INDEX(Tasks!$A:$A,$A6)="","",INDEX(Tasks!$A:$A,$A6))) -> TB-2 | C6: =IF($A6="","",IF(ISERROR(FIND(".",INDEX(Tasks!$A:$A,$A6))),""," ")&INDEX(Tasks!$C:$C,$A6)) -> Sensor calibration (all units) | D6: =IF($A6="","",IF(INDEX(Tasks!$D:$D,$A6)="","",INDEX(Tasks!$D:$D,$A6))) -> Sensors & platform owner | E6: =IF($A6="","",IF(INDEX(Tasks!$E:$E,$A6)="","",INDEX(Tasks!$E:$E,$A6))) -> In Progress | F6: =IF($A6="","",IF(INDEX(Tasks!$F:$F,$A6)="","",INDEX(Tasks!$F:$F,$A6))) -> 46195 | G6: =IF($A6="","",IF(INDEX(Tasks!$H:$H,$A6)="","",INDEX(Tasks!$H:$H,$A6))) -> 46206 | BB6: In Progress
A7: =IFERROR(MATCH($C$2&"|"&(ROW()-4),Tasks!$L$4:$L$403,0)+3,"") -> 6 | B7: =IF($A7="","",IF(INDEX(Tasks!$A:$A,$A7)="","",INDEX(Tasks!$A:$A,$A7))) -> TB-2.1 | C7: =IF($A7="","",IF(ISERROR(FIND(".",INDEX(Tasks!$A:$A,$A7))),""," ")&INDEX(Tasks!$C:$C,$A7)) -> Sensor Calibration (LiDAR-Camera, LiDAR-IMU, Camera-Radar, Intrinsics, Realsense-Zed, Mobile-Infra Extrinsics) | D7: =IF($A7="","",IF(INDEX(Tasks!$D:$D,$A7)="","",INDEX(Tasks!$D:$D,$A7))) -> Sensors & platform owner | E7: =IF($A7="","",IF(INDEX(Tasks!$E:$E,$A7)="","",INDEX(Tasks!$E:$E,$A7))) -> In Progress | F7: =IF($A7="","",IF(INDEX(Tasks!$F:$F,$A7)="","",INDEX(Tasks!$F:$F,$A7))) -> 46195 | G7: =IF($A7="","",IF(INDEX(Tasks!$H:$H,$A7)="","",INDEX(Tasks!$H:$H,$A7))) -> 46206 | BB7: Partially Completed
A8: =IFERROR(MATCH($C$2&"|"&(ROW()-4),Tasks!$L$4:$L$403,0)+3,"") -> 7 | B8: =IF($A8="","",IF(INDEX(Tasks!$A:$A,$A8)="","",INDEX(Tasks!$A:$A,$A8))) -> TB-2.2 | C8: =IF($A8="","",IF(ISERROR(FIND(".",INDEX(Tasks!$A:$A,$A8))),""," ")&INDEX(Tasks!$C:$C,$A8)) -> Calibration: LiDAR - Camera | D8: =IF($A8="","",IF(INDEX(Tasks!$D:$D,$A8)="","",INDEX(Tasks!$D:$D,$A8))) -> Sensors & platform owner | E8: =IF($A8="","",IF(INDEX(Tasks!$E:$E,$A8)="","",INDEX(Tasks!$E:$E,$A8))) | F8: =IF($A8="","",IF(INDEX(Tasks!$F:$F,$A8)="","",INDEX(Tasks!$F:$F,$A8))) | G8: =IF($A8="","",IF(INDEX(Tasks!$H:$H,$A8)="","",INDEX(Tasks!$H:$H,$A8))) | BB8: Blocked
A9: =IFERROR(MATCH($C$2&"|"&(ROW()-4),Tasks!$L$4:$L$403,0)+3,"") -> 8 | B9: =IF($A9="","",IF(INDEX(Tasks!$A:$A,$A9)="","",INDEX(Tasks!$A:$A,$A9))) -> TB-2.3 | C9: =IF($A9="","",IF(ISERROR(FIND(".",INDEX(Tasks!$A:$A,$A9))),""," ")&INDEX(Tasks!$C:$C,$A9)) -> Calibration: LiDAR - IMU | D9: =IF($A9="","",IF(INDEX(Tasks!$D:$D,$A9)="","",INDEX(Tasks!$D:$D,$A9))) -> Sensors & platform owner | E9: =IF($A9="","",IF(INDEX(Tasks!$E:$E,$A9)="","",INDEX(Tasks!$E:$E,$A9))) | F9: =IF($A9="","",IF(INDEX(Tasks!$F:$F,$A9)="","",INDEX(Tasks!$F:$F,$A9))) | G9: =IF($A9="","",IF(INDEX(Tasks!$H:$H,$A9)="","",INDEX(Tasks!$H:$H,$A9))) | BB9: Not Started
A10: =IFERROR(MATCH($C$2&"|"&(ROW()-4),Tasks!$L$4:$L$403,0)+3,"") -> 9 | B10: =IF($A10="","",IF(INDEX(Tasks!$A:$A,$A10)="","",INDEX(Tasks!$A:$A,$A10))) -> TB-2.4 | C10: =IF($A10="","",IF(ISERROR(FIND(".",INDEX(Tasks!$A:$A,$A10))),""," ")&INDEX(Tasks!$C:$C,$A10)) -> Calibration: RealSense - ZED | D10: =IF($A10="","",IF(INDEX(Tasks!$D:$D,$A10)="","",INDEX(Tasks!$D:$D,$A10))) -> Sensors & platform owner | E10: =IF($A10="","",IF(INDEX(Tasks!$E:$E,$A10)="","",INDEX(Tasks!$E:$E,$A10))) | F10: =IF($A10="","",IF(INDEX(Tasks!$F:$F,$A10)="","",INDEX(Tasks!$F:$F,$A10))) | G10: =IF($A10="","",IF(INDEX(Tasks!$H:$H,$A10)="","",INDEX(Tasks!$H:$H,$A10))) | BB10: Milestone
A11: =IFERROR(MATCH($C$2&"|"&(ROW()-4),Tasks!$L$4:$L$403,0)+3,"") -> 10 | B11: =IF($A11="","",IF(INDEX(Tasks!$A:$A,$A11)="","",INDEX(Tasks!$A:$A,$A11))) -> TB-2.5 | C11: =IF($A11="","",IF(ISERROR(FIND(".",INDEX(Tasks!$A:$A,$A11))),""," ")&INDEX(Tasks!$C:$C,$A11)) -> Calibration: ZED - Arducam | D11: =IF($A11="","",IF(INDEX(Tasks!$D:$D,$A11)="","",INDEX(Tasks!$D:$D,$A11))) -> Sensors & platform owner | E11: =IF($A11="","",IF(INDEX(Tasks!$E:$E,$A11)="","",INDEX(Tasks!$E:$E,$A11))) | F11: =IF($A11="","",IF(INDEX(Tasks!$F:$F,$A11)="","",INDEX(Tasks!$F:$F,$A11))) | G11: =IF($A11="","",IF(INDEX(Tasks!$H:$H,$A11)="","",INDEX(Tasks!$H:$H,$A11))) | BB11: Today's week
A12: =IFERROR(MATCH($C$2&"|"&(ROW()-4),Tasks!$L$4:$L$403,0)+3,"") -> 11 | B12: =IF($A12="","",IF(INDEX(Tasks!$A:$A,$A12)="","",INDEX(Tasks!$A:$A,$A12))) -> TB-2.6 | C12: =IF($A12="","",IF(ISERROR(FIND(".",INDEX(Tasks!$A:$A,$A12))),""," ")&INDEX(Tasks!$C:$C,$A12)) -> Calibration: Radars - ZED | D12: =IF($A12="","",IF(INDEX(Tasks!$D:$D,$A12)="","",INDEX(Tasks!$D:$D,$A12))) -> Sensors & platform owner | E12: =IF($A12="","",IF(INDEX(Tasks!$E:$E,$A12)="","",INDEX(Tasks!$E:$E,$A12))) | F12: =IF($A12="","",IF(INDEX(Tasks!$F:$F,$A12)="","",INDEX(Tasks!$F:$F,$A12))) | G12: =IF($A12="","",IF(INDEX(Tasks!$H:$H,$A12)="","",INDEX(Tasks!$H:$H,$A12)))
A13: =IFERROR(MATCH($C$2&"|"&(ROW()-4),Tasks!$L$4:$L$403,0)+3,"") -> 12 | B13: =IF($A13="","",IF(INDEX(Tasks!$A:$A,$A13)="","",INDEX(Tasks!$A:$A,$A13))) -> TB-3 | C13: =IF($A13="","",IF(ISERROR(FIND(".",INDEX(Tasks!$A:$A,$A13))),""," ")&INDEX(Tasks!$C:$C,$A13)) -> Time sync & TF chain | D13: =IF($A13="","",IF(INDEX(Tasks!$D:$D,$A13)="","",INDEX(Tasks!$D:$D,$A13))) -> Sensors & platform owner | E13: =IF($A13="","",IF(INDEX(Tasks!$E:$E,$A13)="","",INDEX(Tasks!$E:$E,$A13))) -> In Progress | F13: =IF($A13="","",IF(INDEX(Tasks!$F:$F,$A13)="","",INDEX(Tasks!$F:$F,$A13))) -> 46202 | G13: =IF($A13="","",IF(INDEX(Tasks!$H:$H,$A13)="","",INDEX(Tasks!$H:$H,$A13))) -> 46206 | BB13: Red End = overdue
A14: =IFERROR(MATCH($C$2&"|"&(ROW()-4),Tasks!$L$4:$L$403,0)+3,"") -> 13 | B14: =IF($A14="","",IF(INDEX(Tasks!$A:$A,$A14)="","",INDEX(Tasks!$A:$A,$A14))) -> TB-4 | C14: =IF($A14="","",IF(ISERROR(FIND(".",INDEX(Tasks!$A:$A,$A14))),""," ")&INDEX(Tasks!$C:$C,$A14)) -> Wi-Fi & comms logging | D14: =IF($A14="","",IF(INDEX(Tasks!$D:$D,$A14)="","",INDEX(Tasks!$D:$D,$A14))) -> Sensors & platform owner | E14: =IF($A14="","",IF(INDEX(Tasks!$E:$E,$A14)="","",INDEX(Tasks!$E:$E,$A14))) -> In Progress | F14: =IF($A14="","",IF(INDEX(Tasks!$F:$F,$A14)="","",INDEX(Tasks!$F:$F,$A14))) -> 46307 | G14: =IF($A14="","",IF(INDEX(Tasks!$H:$H,$A14)="","",INDEX(Tasks!$H:$H,$A14))) -> 46318
A15: =IFERROR(MATCH($C$2&"|"&(ROW()-4),Tasks!$L$4:$L$403,0)+3,"") -> 14 | B15: =IF($A15="","",IF(INDEX(Tasks!$A:$A,$A15)="","",INDEX(Tasks!$A:$A,$A15))) -> TB-5 | C15: =IF($A15="","",IF(ISERROR(FIND(".",INDEX(Tasks!$A:$A,$A15))),""," ")&INDEX(Tasks!$C:$C,$A15)) -> Recording tooling fixes | D15: =IF($A15="","",IF(INDEX(Tasks!$D:$D,$A15)="","",INDEX(Tasks!$D:$D,$A15))) -> Sensors & platform owner | E15: =IF($A15="","",IF(INDEX(Tasks!$E:$E,$A15)="","",INDEX(Tasks!$E:$E,$A15))) -> Not Started | F15: =IF($A15="","",IF(INDEX(Tasks!$F:$F,$A15)="","",INDEX(Tasks!$F:$F,$A15))) -> 46307 | G15: =IF($A15="","",IF(INDEX(Tasks!$H:$H,$A15)="","",INDEX(Tasks!$H:$H,$A15))) -> 46318
A16: =IFERROR(MATCH($C$2&"|"&(ROW()-4),Tasks!$L$4:$L$403,0)+3,"") -> 15 | B16: =IF($A16="","",IF(INDEX(Tasks!$A:$A,$A16)="","",INDEX(Tasks!$A:$A,$A16))) -> G2-DS-1 | C16: =IF($A16="","",IF(ISERROR(FIND(".",INDEX(Tasks!$A:$A,$A16))),""," ")&INDEX(Tasks!$C:$C,$A16)) -> Recording campaign | D16: =IF($A16="","",IF(INDEX(Tasks!$D:$D,$A16)="","",INDEX(Tasks!$D:$D,$A16))) -> SCooP owner | E16: =IF($A16="","",IF(INDEX(Tasks!$E:$E,$A16)="","",INDEX(Tasks!$E:$E,$A16))) -> Partially Completed | F16: =IF($A16="","",IF(INDEX(Tasks!$F:$F,$A16)="","",INDEX(Tasks!$F:$F,$A16))) -> 46314 | G16: =IF($A16="","",IF(INDEX(Tasks!$H:$H,$A16)="","",INDEX(Tasks!$H:$H,$A16))) -> 46353
A17: =IFERROR(MATCH($C$2&"|"&(ROW()-4),Tasks!$L$4:$L$403,0)+3,"") -> 16 | B17: =IF($A17="","",IF(INDEX(Tasks!$A:$A,$A17)="","",INDEX(Tasks!$A:$A,$A17))) -> G2-DS-1.1 | C17: =IF($A17="","",IF(ISERROR(FIND(".",INDEX(Tasks!$A:$A,$A17))),""," ")&INDEX(Tasks!$C:$C,$A17)) -> Indoor Trajectory Sessions | D17: =IF($A17="","",IF(INDEX(Tasks!$D:$D,$A17)="","",INDEX(Tasks!$D:$D,$A17))) -> SCooP owner | E17: =IF($A17="","",IF(INDEX(Tasks!$E:$E,$A17)="","",INDEX(Tasks!$E:$E,$A17))) -> Partially Completed | F17: =IF($A17="","",IF(INDEX(Tasks!$F:$F,$A17)="","",INDEX(Tasks!$F:$F,$A17))) -> 46202 | G17: =IF($A17="","",IF(INDEX(Tasks!$H:$H,$A17)="","",INDEX(Tasks!$H:$H,$A17))) -> 46206
A18: =IFERROR(MATCH($C$2&"|"&(ROW()-4),Tasks!$L$4:$L$403,0)+3,"") -> 17 | B18: =IF($A18="","",IF(INDEX(Tasks!$A:$A,$A18)="","",INDEX(Tasks!$A:$A,$A18))) -> G2-DS-1.2 | C18: =IF($A18="","",IF(ISERROR(FIND(".",INDEX(Tasks!$A:$A,$A18))),""," ")&INDEX(Tasks!$C:$C,$A18)) -> Outdoor Trajectory Sessions | D18: =IF($A18="","",IF(INDEX(Tasks!$D:$D,$A18)="","",INDEX(Tasks!$D:$D,$A18))) -> SCooP owner | E18: =IF($A18="","",IF(INDEX(Tasks!$E:$E,$A18)="","",INDEX(Tasks!$E:$E,$A18))) -> Not Started | F18: =IF($A18="","",IF(INDEX(Tasks!$F:$F,$A18)="","",INDEX(Tasks!$F:$F,$A18))) | G18: =IF($A18="","",IF(INDEX(Tasks!$H:$H,$A18)="","",INDEX(Tasks!$H:$H,$A18)))
A19: =IFERROR(MATCH($C$2&"|"&(ROW()-4),Tasks!$L$4:$L$403,0)+3,"") -> 18 | B19: =IF($A19="","",IF(INDEX(Tasks!$A:$A,$A19)="","",INDEX(Tasks!$A:$A,$A19))) -> G2-DS-1.3 | C19: =IF($A19="","",IF(ISERROR(FIND(".",INDEX(Tasks!$A:$A,$A19))),""," ")&INDEX(Tasks!$C:$C,$A19)) -> Record sites 2 and 3 | D19: =IF($A19="","",IF(INDEX(Tasks!$D:$D,$A19)="","",INDEX(Tasks!$D:$D,$A19))) -> SCooP owner | E19: =IF($A19="","",IF(INDEX(Tasks!$E:$E,$A19)="","",INDEX(Tasks!$E:$E,$A19))) -> Not Started | F19: =IF($A19="","",IF(INDEX(Tasks!$F:$F,$A19)="","",INDEX(Tasks!$F:$F,$A19))) -> 46321 | G19: =IF($A19="","",IF(INDEX(Tasks!$H:$H,$A19)="","",INDEX(Tasks!$H:$H,$A19))) -> 46346
A20: =IFERROR(MATCH($C$2&"|"&(ROW()-4),Tasks!$L$4:$L$403,0)+3,"") -> 19 | B20: =IF($A20="","",IF(INDEX(Tasks!$A:$A,$A20)="","",INDEX(Tasks!$A:$A,$A20))) -> G2-DS-1.4 | C20: =IF($A20="","",IF(ISERROR(FIND(".",INDEX(Tasks!$A:$A,$A20))),""," ")&INDEX(Tasks!$C:$C,$A20)) -> Calibration rosbag | D20: =IF($A20="","",IF(INDEX(Tasks!$D:$D,$A20)="","",INDEX(Tasks!$D:$D,$A20))) -> SCooP owner | E20: =IF($A20="","",IF(INDEX(Tasks!$E:$E,$A20)="","",INDEX(Tasks!$E:$E,$A20))) | F20: =IF($A20="","",IF(INDEX(Tasks!$F:$F,$A20)="","",INDEX(Tasks!$F:$F,$A20))) -> 46314 | G20: =IF($A20="","",IF(INDEX(Tasks!$H:$H,$A20)="","",INDEX(Tasks!$H:$H,$A20))) -> 46318
A21: =IFERROR(MATCH($C$2&"|"&(ROW()-4),Tasks!$L$4:$L$403,0)+3,"") -> 20 | B21: =IF($A21="","",IF(INDEX(Tasks!$A:$A,$A21)="","",INDEX(Tasks!$A:$A,$A21))) -> G2-DS-1.5 | C21: =IF($A21="","",IF(ISERROR(FIND(".",INDEX(Tasks!$A:$A,$A21))),""," ")&INDEX(Tasks!$C:$C,$A21)) -> Short test recordings | D21: =IF($A21="","",IF(INDEX(Tasks!$D:$D,$A21)="","",INDEX(Tasks!$D:$D,$A21))) -> SCooP owner | E21: =IF($A21="","",IF(INDEX(Tasks!$E:$E,$A21)="","",INDEX(Tasks!$E:$E,$A21))) | F21: =IF($A21="","",IF(INDEX(Tasks!$F:$F,$A21)="","",INDEX(Tasks!$F:$F,$A21))) -> 46314 | G21: =IF($A21="","",IF(INDEX(Tasks!$H:$H,$A21)="","",INDEX(Tasks!$H:$H,$A21))) -> 46318
A22: =IFERROR(MATCH($C$2&"|"&(ROW()-4),Tasks!$L$4:$L$403,0)+3,"") -> 21 | B22: =IF($A22="","",IF(INDEX(Tasks!$A:$A,$A22)="","",INDEX(Tasks!$A:$A,$A22))) -> G2-DS-2 | C22: =IF($A22="","",IF(ISERROR(FIND(".",INDEX(Tasks!$A:$A,$A22))),""," ")&INDEX(Tasks!$C:$C,$A22)) -> Per-pass processing | D22: =IF($A22="","",IF(INDEX(Tasks!$D:$D,$A22)="","",INDEX(Tasks!$D:$D,$A22))) -> SCooP owner | E22: =IF($A22="","",IF(INDEX(Tasks!$E:$E,$A22)="","",INDEX(Tasks!$E:$E,$A22))) -> In Progress | F22: =IF($A22="","",IF(INDEX(Tasks!$F:$F,$A22)="","",INDEX(Tasks!$F:$F,$A22))) -> 46307 | G22: =IF($A22="","",IF(INDEX(Tasks!$H:$H,$A22)="","",INDEX(Tasks!$H:$H,$A22))) -> 46374
A23: =IFERROR(MATCH($C$2&"|"&(ROW()-4),Tasks!$L$4:$L$403,0)+3,"") -> 22 | B23: =IF($A23="","",IF(INDEX(Tasks!$A:$A,$A23)="","",INDEX(Tasks!$A:$A,$A23))) -> G2-DS-2.1 | C23: =IF($A23="","",IF(ISERROR(FIND(".",INDEX(Tasks!$A:$A,$A23))),""," ")&INDEX(Tasks!$C:$C,$A23)) -> Merging Sensor Data | D23: =IF($A23="","",IF(INDEX(Tasks!$D:$D,$A23)="","",INDEX(Tasks!$D:$D,$A23))) -> SCooP owner | E23: =IF($A23="","",IF(INDEX(Tasks!$E:$E,$A23)="","",INDEX(Tasks!$E:$E,$A23))) -> In Progress | F23: =IF($A23="","",IF(INDEX(Tasks!$F:$F,$A23)="","",INDEX(Tasks!$F:$F,$A23))) -> 46202 | G23: =IF($A23="","",IF(INDEX(Tasks!$H:$H,$A23)="","",INDEX(Tasks!$H:$H,$A23))) -> 46206
A24: =IFERROR(MATCH($C$2&"|"&(ROW()-4),Tasks!$L$4:$L$403,0)+3,"") -> 23 | B24: =IF($A24="","",IF(INDEX(Tasks!$A:$A,$A24)="","",INDEX(Tasks!$A:$A,$A24))) -> G2-DS-2.2 | C24: =IF($A24="","",IF(ISERROR(FIND(".",INDEX(Tasks!$A:$A,$A24))),""," ")&INDEX(Tasks!$C:$C,$A24)) -> Timestamp Alignment Post-Processing | D24: =IF($A24="","",IF(INDEX(Tasks!$D:$D,$A24)="","",INDEX(Tasks!$D:$D,$A24))) -> SCooP owner | E24: =IF($A24="","",IF(INDEX(Tasks!$E:$E,$A24)="","",INDEX(Tasks!$E:$E,$A24))) -> Not Started | F24: =IF($A24="","",IF(INDEX(Tasks!$F:$F,$A24)="","",INDEX(Tasks!$F:$F,$A24))) -> 46202 | G24: =IF($A24="","",IF(INDEX(Tasks!$H:$H,$A24)="","",INDEX(Tasks!$H:$H,$A24))) -> 46206
A25: =IFERROR(MATCH($C$2&"|"&(ROW()-4),Tasks!$L$4:$L$403,0)+3,"") -> 24 | B25: =IF($A25="","",IF(INDEX(Tasks!$A:$A,$A25)="","",INDEX(Tasks!$A:$A,$A25))) -> G2-DS-3 | C25: =IF($A25="","",IF(ISERROR(FIND(".",INDEX(Tasks!$A:$A,$A25))),""," ")&INDEX(Tasks!$C:$C,$A25)) -> Reference maps & board networks per site | D25: =IF($A25="","",IF(INDEX(Tasks!$D:$D,$A25)="","",INDEX(Tasks!$D:$D,$A25))) -> SCooP owner | E25: =IF($A25="","",IF(INDEX(Tasks!$E:$E,$A25)="","",INDEX(Tasks!$E:$E,$A25))) -> In Progress | F25: =IF($A25="","",IF(INDEX(Tasks!$F:$F,$A25)="","",INDEX(Tasks!$F:$F,$A25))) -> 46307 | G25: =IF($A25="","",IF(INDEX(Tasks!$H:$H,$A25)="","",INDEX(Tasks!$H:$H,$A25))) -> 46360
... A404: =IFERROR(MATCH($C$2&"|"&(ROW()-4),Tasks!$L$4:$L$403,0)+3,"") | B404: =IF($A404="","",IF(INDEX(Tasks!$A:$A,$A404)="","",INDEX(Tasks!$A:$A,$A404))) | C404: =IF($A404="","",IF(ISERROR(FIND(".",INDEX(Tasks!$A:$A,$A404))),""," ")&INDEX(Tasks!$C:$C,$A404)) | D404: =IF($A404="","",IF(INDEX(Tasks!$D:$D,$A404)="","",INDEX(Tasks!$D:$D,$A404))) | E404: =IF($A404="","",IF(INDEX(Tasks!$E:$E,$A404)="","",INDEX(Tasks!$E:$E,$A404))) | F404: =IF($A404="","",IF(INDEX(Tasks!$F:$F,$A404)="","",INDEX(Tasks!$F:$F,$A404))) | G404: =IF($A404="","",IF(INDEX(Tasks!$H:$H,$A404)="","",INDEX(Tasks!$H:$H,$A404)))

Sheet G1 Digital twin
B1: Goal: G1 ED305 live digital twin
B2: Goal: | C2: G1 ED305 live digital twin | E2: =COUNTIFS(Tasks!$B$4:$B$403,$C$2,Tasks!$C$4:$C$403,"?*")&" tasks · "&COUNTIFS(Tasks!$B$4:$B$403,$C$2,Tasks!$C$4:$C$403,"?*",Tasks!$E$4:$E$403,"In Progress")&" in progress · "&COUNTIFS(Tasks!$B$4:$B$403,$C$2,Tasks!$C$4:$C$403,"?*",Tasks!$E$4:$E$403,"Blocked")&" blocked · "&COUNTIFS(Tasks!$B$4:$B$403,$C$2,Tasks!$C$4:$C$403,"?*",Tasks!$H$4:$H$403,"<"&TODAY(),Tasks!$E$4:$E$403,"<>Complete")&" overdue" -> 43 tasks · 1 in progress · 1 blocked · 6 overdue
A4: Tasks row | B4: ID | C4: Task | D4: Assigned to | E4: Status | F4: Start | G4: End | H4: =Gantt!$C$3+7*0 -> 46195 | I4: =Gantt!$C$3+7*1 -> 46202 | J4: =Gantt!$C$3+7*2 -> 46209 | K4: =Gantt!$C$3+7*3 -> 46216 | L4: =Gantt!$C$3+7*4 -> 46223 | M4: =Gantt!$C$3+7*5 -> 46230 | N4: =Gantt!$C$3+7*6 -> 46237 | O4: =Gantt!$C$3+7*7 -> 46244 | P4: =Gantt!$C$3+7*8 -> 46251 | Q4: =Gantt!$C$3+7*9 -> 46258 | R4: =Gantt!$C$3+7*10 -> 46265 | S4: =Gantt!$C$3+7*11 -> 46272 | T4: =Gantt!$C$3+7*12 -> 46279 | U4: =Gantt!$C$3+7*13 -> 46286 | V4: =Gantt!$C$3+7*14 -> 46293 | W4: =Gantt!$C$3+7*15 -> 46300 | X4: =Gantt!$C$3+7*16 -> 46307 | Y4: =Gantt!$C$3+7*17 -> 46314 | Z4: =Gantt!$C$3+7*18 -> 46321 | AA4: =Gantt!$C$3+7*19 -> 46328 | AB4: =Gantt!$C$3+7*20 -> 46335 | AC4: =Gantt!$C$3+7*21 -> 46342 | AD4: =Gantt!$C$3+7*22 -> 46349 | AE4: =Gantt!$C$3+7*23 -> 46356 | AF4: =Gantt!$C$3+7*24 -> 46363 | AG4: =Gantt!$C$3+7*25 -> 46370 | AH4: =Gantt!$C$3+7*26 -> 46377 | AI4: =Gantt!$C$3+7*27 -> 46384 | AJ4: =Gantt!$C$3+7*28 -> 46391 | AK4: =Gantt!$C$3+7*29 -> 46398 | AL4: =Gantt!$C$3+7*30 -> 46405 | AM4: =Gantt!$C$3+7*31 -> 46412 | AN4: =Gantt!$C$3+7*32 -> 46419 | AO4: =Gantt!$C$3+7*33 -> 46426 | AP4: =Gantt!$C$3+7*34 -> 46433 | AQ4: =Gantt!$C$3+7*35 -> 46440 | AR4: =Gantt!$C$3+7*36 -> 46447 | AS4: =Gantt!$C$3+7*37 -> 46454 | AT4: =Gantt!$C$3+7*38 -> 46461 | AU4: =Gantt!$C$3+7*39 -> 46468 | AV4: =Gantt!$C$3+7*40 -> 46475 | AW4: =Gantt!$C$3+7*41 -> 46482 | AX4: =Gantt!$C$3+7*42 -> 46489 | AY4: =Gantt!$C$3+7*43 -> 46496 | BB4: Legend
A5: =IFERROR(MATCH($C$2&"|"&(ROW()-4),Tasks!$K$4:$K$403,0)+3,"") -> 44 | B5: =IF($A5="","",IF(INDEX(Tasks!$A:$A,$A5)="","",INDEX(Tasks!$A:$A,$A5))) -> G1-SP-1 | C5: =IF($A5="","",IF(ISERROR(FIND(".",INDEX(Tasks!$A:$A,$A5))),""," ")&INDEX(Tasks!$C:$C,$A5)) -> Sensor rig & TF tree per robot | D5: =IF($A5="","",IF(INDEX(Tasks!$D:$D,$A5)="","",INDEX(Tasks!$D:$D,$A5))) -> Sensors & platform owner | E5: =IF($A5="","",IF(INDEX(Tasks!$E:$E,$A5)="","",INDEX(Tasks!$E:$E,$A5))) -> Not Started | F5: =IF($A5="","",IF(INDEX(Tasks!$F:$F,$A5)="","",INDEX(Tasks!$F:$F,$A5))) -> 46307 | G5: =IF($A5="","",IF(INDEX(Tasks!$H:$H,$A5)="","",INDEX(Tasks!$H:$H,$A5))) -> 46318 | BB5: Complete
A6: =IFERROR(MATCH($C$2&"|"&(ROW()-4),Tasks!$K$4:$K$403,0)+3,"") -> 45 | B6: =IF($A6="","",IF(INDEX(Tasks!$A:$A,$A6)="","",INDEX(Tasks!$A:$A,$A6))) -> G1-SP-2 | C6: =IF($A6="","",IF(ISERROR(FIND(".",INDEX(Tasks!$A:$A,$A6))),""," ")&INDEX(Tasks!$C:$C,$A6)) -> Odometry: front end + fusion filter | D6: =IF($A6="","",IF(INDEX(Tasks!$D:$D,$A6)="","",INDEX(Tasks!$D:$D,$A6))) -> Sensors & platform owner | E6: =IF($A6="","",IF(INDEX(Tasks!$E:$E,$A6)="","",INDEX(Tasks!$E:$E,$A6))) -> Not Started | F6: =IF($A6="","",IF(INDEX(Tasks!$F:$F,$A6)="","",INDEX(Tasks!$F:$F,$A6))) -> 46314 | G6: =IF($A6="","",IF(INDEX(Tasks!$H:$H,$A6)="","",INDEX(Tasks!$H:$H,$A6))) -> 46339 | BB6: In Progress
A7: =IFERROR(MATCH($C$2&"|"&(ROW()-4),Tasks!$K$4:$K$403,0)+3,"") -> 46 | B7: =IF($A7="","",IF(INDEX(Tasks!$A:$A,$A7)="","",INDEX(Tasks!$A:$A,$A7))) -> G1-SP-3 | C7: =IF($A7="","",IF(ISERROR(FIND(".",INDEX(Tasks!$A:$A,$A7))),""," ")&INDEX(Tasks!$C:$C,$A7)) -> ED305 camera calibration in the room frame | D7: =IF($A7="","",IF(INDEX(Tasks!$D:$D,$A7)="","",INDEX(Tasks!$D:$D,$A7))) -> Sensors & platform owner | E7: =IF($A7="","",IF(INDEX(Tasks!$E:$E,$A7)="","",INDEX(Tasks!$E:$E,$A7))) -> Blocked | F7: =IF($A7="","",IF(INDEX(Tasks!$F:$F,$A7)="","",INDEX(Tasks!$F:$F,$A7))) -> 46307 | G7: =IF($A7="","",IF(INDEX(Tasks!$H:$H,$A7)="","",INDEX(Tasks!$H:$H,$A7))) -> 46318 | BB7: Partially Completed
A8: =IFERROR(MATCH($C$2&"|"&(ROW()-4),Tasks!$K$4:$K$403,0)+3,"") -> 47 | B8: =IF($A8="","",IF(INDEX(Tasks!$A:$A,$A8)="","",INDEX(Tasks!$A:$A,$A8))) -> G1-SP-4 | C8: =IF($A8="","",IF(ISERROR(FIND(".",INDEX(Tasks!$A:$A,$A8))),""," ")&INDEX(Tasks!$C:$C,$A8)) -> ED305 coverage & camera placement | D8: =IF($A8="","",IF(INDEX(Tasks!$D:$D,$A8)="","",INDEX(Tasks!$D:$D,$A8))) -> Sensors & platform owner | E8: =IF($A8="","",IF(INDEX(Tasks!$E:$E,$A8)="","",INDEX(Tasks!$E:$E,$A8))) -> In Progress | F8: =IF($A8="","",IF(INDEX(Tasks!$F:$F,$A8)="","",INDEX(Tasks!$F:$F,$A8))) -> 46321 | G8: =IF($A8="","",IF(INDEX(Tasks!$H:$H,$A8)="","",INDEX(Tasks!$H:$H,$A8))) -> 46339 | BB8: Blocked
A9: =IFERROR(MATCH($C$2&"|"&(ROW()-4),Tasks!$K$4:$K$403,0)+3,"") -> 48 | B9: =IF($A9="","",IF(INDEX(Tasks!$A:$A,$A9)="","",INDEX(Tasks!$A:$A,$A9))) -> G1-SP-5 | C9: =IF($A9="","",IF(ISERROR(FIND(".",INDEX(Tasks!$A:$A,$A9))),""," ")&INDEX(Tasks!$C:$C,$A9)) -> Printed pan-tilt heads | D9: =IF($A9="","",IF(INDEX(Tasks!$D:$D,$A9)="","",INDEX(Tasks!$D:$D,$A9))) -> Sensors & platform owner | E9: =IF($A9="","",IF(INDEX(Tasks!$E:$E,$A9)="","",INDEX(Tasks!$E:$E,$A9))) -> Not Started | F9: =IF($A9="","",IF(INDEX(Tasks!$F:$F,$A9)="","",INDEX(Tasks!$F:$F,$A9))) -> 46314 | G9: =IF($A9="","",IF(INDEX(Tasks!$H:$H,$A9)="","",INDEX(Tasks!$H:$H,$A9))) -> 46332 | BB9: Not Started
A10: =IFERROR(MATCH($C$2&"|"&(ROW()-4),Tasks!$K$4:$K$403,0)+3,"") -> 49 | B10: =IF($A10="","",IF(INDEX(Tasks!$A:$A,$A10)="","",INDEX(Tasks!$A:$A,$A10))) -> G1-SP-6 | C10: =IF($A10="","",IF(ISERROR(FIND(".",INDEX(Tasks!$A:$A,$A10))),""," ")&INDEX(Tasks!$C:$C,$A10)) -> ED305 camera time sync | D10: =IF($A10="","",IF(INDEX(Tasks!$D:$D,$A10)="","",INDEX(Tasks!$D:$D,$A10))) -> Sensors & platform owner | E10: =IF($A10="","",IF(INDEX(Tasks!$E:$E,$A10)="","",INDEX(Tasks!$E:$E,$A10))) -> Not Started | F10: =IF($A10="","",IF(INDEX(Tasks!$F:$F,$A10)="","",INDEX(Tasks!$F:$F,$A10))) -> 46321 | G10: =IF($A10="","",IF(INDEX(Tasks!$H:$H,$A10)="","",INDEX(Tasks!$H:$H,$A10))) -> 46332 | BB10: Milestone
A11: =IFERROR(MATCH($C$2&"|"&(ROW()-4),Tasks!$K$4:$K$403,0)+3,"") -> 50 | B11: =IF($A11="","",IF(INDEX(Tasks!$A:$A,$A11)="","",INDEX(Tasks!$A:$A,$A11))) -> G1-GS-1 | C11: =IF($A11="","",IF(ISERROR(FIND(".",INDEX(Tasks!$A:$A,$A11))),""," ")&INDEX(Tasks!$C:$C,$A11)) -> Metric prior | D11: =IF($A11="","",IF(INDEX(Tasks!$D:$D,$A11)="","",INDEX(Tasks!$D:$D,$A11))) -> GS-SLAM owner | E11: =IF($A11="","",IF(INDEX(Tasks!$E:$E,$A11)="","",INDEX(Tasks!$E:$E,$A11))) -> Not Started | F11: =IF($A11="","",IF(INDEX(Tasks!$F:$F,$A11)="","",INDEX(Tasks!$F:$F,$A11))) -> 46307 | G11: =IF($A11="","",IF(INDEX(Tasks!$H:$H,$A11)="","",INDEX(Tasks!$H:$H,$A11))) -> 46318 | BB11: Today's week
A12: =IFERROR(MATCH($C$2&"|"&(ROW()-4),Tasks!$K$4:$K$403,0)+3,"") -> 51 | B12: =IF($A12="","",IF(INDEX(Tasks!$A:$A,$A12)="","",INDEX(Tasks!$A:$A,$A12))) -> G1-GS-2 | C12: =IF($A12="","",IF(ISERROR(FIND(".",INDEX(Tasks!$A:$A,$A12))),""," ")&INDEX(Tasks!$C:$C,$A12)) -> Tracking + keyframe gate | D12: =IF($A12="","",IF(INDEX(Tasks!$D:$D,$A12)="","",INDEX(Tasks!$D:$D,$A12))) -> GS-SLAM owner | E12: =IF($A12="","",IF(INDEX(Tasks!$E:$E,$A12)="","",INDEX(Tasks!$E:$E,$A12))) -> Not Started | F12: =IF($A12="","",IF(INDEX(Tasks!$F:$F,$A12)="","",INDEX(Tasks!$F:$F,$A12))) -> 46314 | G12: =IF($A12="","",IF(INDEX(Tasks!$H:$H,$A12)="","",INDEX(Tasks!$H:$H,$A12))) -> 46339
A13: =IFERROR(MATCH($C$2&"|"&(ROW()-4),Tasks!$K$4:$K$403,0)+3,"") -> 52 | B13: =IF($A13="","",IF(INDEX(Tasks!$A:$A,$A13)="","",INDEX(Tasks!$A:$A,$A13))) -> G1-GS-3 | C13: =IF($A13="","",IF(ISERROR(FIND(".",INDEX(Tasks!$A:$A,$A13))),""," ")&INDEX(Tasks!$C:$C,$A13)) -> Mapping + loop closure | D13: =IF($A13="","",IF(INDEX(Tasks!$D:$D,$A13)="","",INDEX(Tasks!$D:$D,$A13))) -> GS-SLAM owner | E13: =IF($A13="","",IF(INDEX(Tasks!$E:$E,$A13)="","",INDEX(Tasks!$E:$E,$A13))) -> Not Started | F13: =IF($A13="","",IF(INDEX(Tasks!$F:$F,$A13)="","",INDEX(Tasks!$F:$F,$A13))) -> 46328 | G13: =IF($A13="","",IF(INDEX(Tasks!$H:$H,$A13)="","",INDEX(Tasks!$H:$H,$A13))) -> 46353 | BB13: Red End = overdue
A14: =IFERROR(MATCH($C$2&"|"&(ROW()-4),Tasks!$K$4:$K$403,0)+3,"") -> 53 | B14: =IF($A14="","",IF(INDEX(Tasks!$A:$A,$A14)="","",INDEX(Tasks!$A:$A,$A14))) -> G1-GS-3.1 | C14: =IF($A14="","",IF(ISERROR(FIND(".",INDEX(Tasks!$A:$A,$A14))),""," ")&INDEX(Tasks!$C:$C,$A14)) -> Dynamic-Object Filter (Pre-Registration) | D14: =IF($A14="","",IF(INDEX(Tasks!$D:$D,$A14)="","",INDEX(Tasks!$D:$D,$A14))) -> GS-SLAM owner | E14: =IF($A14="","",IF(INDEX(Tasks!$E:$E,$A14)="","",INDEX(Tasks!$E:$E,$A14))) -> Not Started | F14: =IF($A14="","",IF(INDEX(Tasks!$F:$F,$A14)="","",INDEX(Tasks!$F:$F,$A14))) -> 46202 | G14: =IF($A14="","",IF(INDEX(Tasks!$H:$H,$A14)="","",INDEX(Tasks!$H:$H,$A14))) -> 46206
A15: =IFERROR(MATCH($C$2&"|"&(ROW()-4),Tasks!$K$4:$K$403,0)+3,"") -> 54 | B15: =IF($A15="","",IF(INDEX(Tasks!$A:$A,$A15)="","",INDEX(Tasks!$A:$A,$A15))) -> G1-GS-3.2 | C15: =IF($A15="","",IF(ISERROR(FIND(".",INDEX(Tasks!$A:$A,$A15))),""," ")&INDEX(Tasks!$C:$C,$A15)) -> Static Point Cloud Registration | D15: =IF($A15="","",IF(INDEX(Tasks!$D:$D,$A15)="","",INDEX(Tasks!$D:$D,$A15))) -> GS-SLAM owner | E15: =IF($A15="","",IF(INDEX(Tasks!$E:$E,$A15)="","",INDEX(Tasks!$E:$E,$A15))) -> Not Started | F15: =IF($A15="","",IF(INDEX(Tasks!$F:$F,$A15)="","",INDEX(Tasks!$F:$F,$A15))) -> 46202 | G15: =IF($A15="","",IF(INDEX(Tasks!$H:$H,$A15)="","",INDEX(Tasks!$H:$H,$A15))) -> 46206
A16: =IFERROR(MATCH($C$2&"|"&(ROW()-4),Tasks!$K$4:$K$403,0)+3,"") -> 55 | B16: =IF($A16="","",IF(INDEX(Tasks!$A:$A,$A16)="","",INDEX(Tasks!$A:$A,$A16))) -> G1-GS-4 | C16: =IF($A16="","",IF(ISERROR(FIND(".",INDEX(Tasks!$A:$A,$A16))),""," ")&INDEX(Tasks!$C:$C,$A16)) -> Real-time budget | D16: =IF($A16="","",IF(INDEX(Tasks!$D:$D,$A16)="","",INDEX(Tasks!$D:$D,$A16))) -> GS-SLAM owner | E16: =IF($A16="","",IF(INDEX(Tasks!$E:$E,$A16)="","",INDEX(Tasks!$E:$E,$A16))) -> Not Started | F16: =IF($A16="","",IF(INDEX(Tasks!$F:$F,$A16)="","",INDEX(Tasks!$F:$F,$A16))) -> 46349 | G16: =IF($A16="","",IF(INDEX(Tasks!$H:$H,$A16)="","",INDEX(Tasks!$H:$H,$A16))) -> 46360
A17: =IFERROR(MATCH($C$2&"|"&(ROW()-4),Tasks!$K$4:$K$403,0)+3,"") -> 56 | B17: =IF($A17="","",IF(INDEX(Tasks!$A:$A,$A17)="","",INDEX(Tasks!$A:$A,$A17))) -> G1-GS-5 | C17: =IF($A17="","",IF(ISERROR(FIND(".",INDEX(Tasks!$A:$A,$A17))),""," ")&INDEX(Tasks!$C:$C,$A17)) -> Map fusion (multi-robot) | D17: =IF($A17="","",IF(INDEX(Tasks!$D:$D,$A17)="","",INDEX(Tasks!$D:$D,$A17))) -> GS-SLAM owner | E17: =IF($A17="","",IF(INDEX(Tasks!$E:$E,$A17)="","",INDEX(Tasks!$E:$E,$A17))) -> Not Started | F17: =IF($A17="","",IF(INDEX(Tasks!$F:$F,$A17)="","",INDEX(Tasks!$F:$F,$A17))) -> 46356 | G17: =IF($A17="","",IF(INDEX(Tasks!$H:$H,$A17)="","",INDEX(Tasks!$H:$H,$A17))) -> 46381
A18: =IFERROR(MATCH($C$2&"|"&(ROW()-4),Tasks!$K$4:$K$403,0)+3,"") -> 57 | B18: =IF($A18="","",IF(INDEX(Tasks!$A:$A,$A18)="","",INDEX(Tasks!$A:$A,$A18))) -> G1-GS-6 | C18: =IF($A18="","",IF(ISERROR(FIND(".",INDEX(Tasks!$A:$A,$A18))),""," ")&INDEX(Tasks!$C:$C,$A18)) -> Evaluation | D18: =IF($A18="","",IF(INDEX(Tasks!$D:$D,$A18)="","",INDEX(Tasks!$D:$D,$A18))) -> GS-SLAM owner | E18: =IF($A18="","",IF(INDEX(Tasks!$E:$E,$A18)="","",INDEX(Tasks!$E:$E,$A18))) -> Not Started | F18: =IF($A18="","",IF(INDEX(Tasks!$F:$F,$A18)="","",INDEX(Tasks!$F:$F,$A18))) -> 46377 | G18: =IF($A18="","",IF(INDEX(Tasks!$H:$H,$A18)="","",INDEX(Tasks!$H:$H,$A18))) -> 46388
A19: =IFERROR(MATCH($C$2&"|"&(ROW()-4),Tasks!$K$4:$K$403,0)+3,"") -> 58 | B19: =IF($A19="","",IF(INDEX(Tasks!$A:$A,$A19)="","",INDEX(Tasks!$A:$A,$A19))) -> G1-SD-1 | C19: =IF($A19="","",IF(ISERROR(FIND(".",INDEX(Tasks!$A:$A,$A19))),""," ")&INDEX(Tasks!$C:$C,$A19)) -> Object asset library | D19: =IF($A19="","",IF(INDEX(Tasks!$D:$D,$A19)="","",INDEX(Tasks!$D:$D,$A19))) -> Scene detection owner | E19: =IF($A19="","",IF(INDEX(Tasks!$E:$E,$A19)="","",INDEX(Tasks!$E:$E,$A19))) -> Not Started | F19: =IF($A19="","",IF(INDEX(Tasks!$F:$F,$A19)="","",INDEX(Tasks!$F:$F,$A19))) -> 46307 | G19: =IF($A19="","",IF(INDEX(Tasks!$H:$H,$A19)="","",INDEX(Tasks!$H:$H,$A19))) -> 46325
