Workbook

Sheet README
A1: Project tracker: ED305 digital twin, SCooP, dual-link, semantic comm
A2: Built from Project_Tracker.xlsx; old tasks kept with their text, status and weeks.
A4: Sheets
A5: Tasks | B5: Every task, one row each. Edit freely, add rows anywhere inside the table. ID: a row whose ID has no '.' is a parent (shown bold).
A6: Gantt | B6: Automatic: bars come from Tasks Start + Weeks, coloured by Status. Change the Gantt start date in Gantt!C2. Nothing to edit by hand.
A7: Problems | B7: Anything that blocks work for more than a day. Link it to the task it blocks (Task ID) and set that task's Status to Blocked.
A8: Interfaces | B8: One row per hand-off between owners (arrows in the system diagram). Move State from Not defined -> Defined -> Implemented -> Tested.
A9: Weekly Log | B9: Every Friday, one row per person: Done / Next / Blockers (problem IDs).
A10: Runs | B10: One row per pipeline run on the server: run ID, data, git commit, key numbers. The server writes the logs; this sheet indexes them.
A11: Dashboard | B11: Counts by goal, owner and status; overdue tasks; open problems; interface states. All formulas.
A12: Lists | B12: Owner names (fill these in) and the dropdown lists.
A14: What to edit
A15: Yellow cells | B15: Settings and owner names: Gantt!C2 (Gantt start), Lists!B (person per role).
A16: Tasks: Start, Weeks | B16: Start = Monday the task starts; Weeks = length. End is computed (Friday of the last week). Leave both empty if not scheduled.
A17: Grey italic columns | B17: Formulas (Person, End). Do not type over them.
A19: Assumptions
A20: Old weeks | B20: Old W1 = Mon 22 Jun 2026. Coloured week cells became Start + Weeks. Rows coloured red across all ten weeks were read as 'not scheduled' (note on each row).
A21: New plan | B21: New tasks start W17 = Mon 12 Oct 2026 (assumed start; shift Start dates as needed).
A22: Statuses | B22: Old statuses kept as they were; new tasks set from the state of the code (e.g. SCooP site 1 processed).
A23: Owners | B23: Owner = role. Put each person's name against the role in Lists; Tasks and Gantt show it.
A25: Google Sheets
A26: Open it | B26: Upload the .xlsx to Google Drive -> open it -> File > Save as Google Sheets. Share the Google Sheet (Editor) with the team; use only that copy.
A27: Rule | B27: Nobody downloads, edits offline and re-uploads: that overwrites everyone else's changes. File > Version history shows who changed what.
A28: Dropdown values | B28: Stored in each column's rule (Data > Data validation). To add a status/role/goal: add it there; also add a new role to Lists so Person can be looked up.

Sheet Dashboard
A1: Dashboard
A2: All numbers are formulas over Tasks, Problems and Interfaces.
A4: Goal | B4: Not Started | C4: In Progress | D4: Blocked | E4: Complete | F4: Partially Completed | G4: No status | H4: Total | I4: Overdue | J4: Not scheduled
A5: G1 ED305 live digital twin | B5: =COUNTIFS(Tasks!$B$4:$B$403,$A5,Tasks!$H$4:$H$403,"Not Started") -> 41 | C5: =COUNTIFS(Tasks!$B$4:$B$403,$A5,Tasks!$H$4:$H$403,"In Progress") -> 1 | D5: =COUNTIFS(Tasks!$B$4:$B$403,$A5,Tasks!$H$4:$H$403,"Blocked") -> 1 | E5: =COUNTIFS(Tasks!$B$4:$B$403,$A5,Tasks!$H$4:$H$403,"Complete") -> 0 | F5: =COUNTIFS(Tasks!$B$4:$B$403,$A5,Tasks!$H$4:$H$403,"Partially Completed") -> 0 | G5: =COUNTIFS(Tasks!$B$4:$B$403,$A5,Tasks!$H$4:$H$403,"") -> 0 | H5: =SUM(B5:G5) -> 43 | I5: =COUNTIFS(Tasks!$B$4:$B$403,$A5,Tasks!$K$4:$K$403,"<"&TODAY(),Tasks!$H$4:$H$403,"<>Complete") -> 6 | J5: =COUNTIFS(Tasks!$B$4:$B$403,$A5,Tasks!$I$4:$I$403,"") -> 0
A6: G2 SCooP dataset & paper | B6: =COUNTIFS(Tasks!$B$4:$B$403,$A6,Tasks!$H$4:$H$403,"Not Started") -> 21 | C6: =COUNTIFS(Tasks!$B$4:$B$403,$A6,Tasks!$H$4:$H$403,"In Progress") -> 4 | D6: =COUNTIFS(Tasks!$B$4:$B$403,$A6,Tasks!$H$4:$H$403,"Blocked") -> 0 | E6: =COUNTIFS(Tasks!$B$4:$B$403,$A6,Tasks!$H$4:$H$403,"Complete") -> 0 | F6: =COUNTIFS(Tasks!$B$4:$B$403,$A6,Tasks!$H$4:$H$403,"Partially Completed") -> 2 | G6: =COUNTIFS(Tasks!$B$4:$B$403,$A6,Tasks!$H$4:$H$403,"") -> 2 | H6: =SUM(B6:G6) -> 29 | I6: =COUNTIFS(Tasks!$B$4:$B$403,$A6,Tasks!$K$4:$K$403,"<"&TODAY(),Tasks!$H$4:$H$403,"<>Complete") -> 5 | J6: =COUNTIFS(Tasks!$B$4:$B$403,$A6,Tasks!$I$4:$I$403,"") -> 3
A7: Shared SCooP testbed | B7: =COUNTIFS(Tasks!$B$4:$B$403,$A7,Tasks!$H$4:$H$403,"Not Started") -> 2 | C7: =COUNTIFS(Tasks!$B$4:$B$403,$A7,Tasks!$H$4:$H$403,"In Progress") -> 4 | D7: =COUNTIFS(Tasks!$B$4:$B$403,$A7,Tasks!$H$4:$H$403,"Blocked") -> 0 | E7: =COUNTIFS(Tasks!$B$4:$B$403,$A7,Tasks!$H$4:$H$403,"Complete") -> 0 | F7: =COUNTIFS(Tasks!$B$4:$B$403,$A7,Tasks!$H$4:$H$403,"Partially Completed") -> 0 | G7: =COUNTIFS(Tasks!$B$4:$B$403,$A7,Tasks!$H$4:$H$403,"") -> 5 | H7: =SUM(B7:G7) -> 11 | I7: =COUNTIFS(Tasks!$B$4:$B$403,$A7,Tasks!$K$4:$K$403,"<"&TODAY(),Tasks!$H$4:$H$403,"<>Complete") -> 3 | J7: =COUNTIFS(Tasks!$B$4:$B$403,$A7,Tasks!$I$4:$I$403,"") -> 5
A8: Dual-Link Communication | B8: =COUNTIFS(Tasks!$B$4:$B$403,$A8,Tasks!$H$4:$H$403,"Not Started") -> 13 | C8: =COUNTIFS(Tasks!$B$4:$B$403,$A8,Tasks!$H$4:$H$403,"In Progress") -> 2 | D8: =COUNTIFS(Tasks!$B$4:$B$403,$A8,Tasks!$H$4:$H$403,"Blocked") -> 0 | E8: =COUNTIFS(Tasks!$B$4:$B$403,$A8,Tasks!$H$4:$H$403,"Complete") -> 0 | F8: =COUNTIFS(Tasks!$B$4:$B$403,$A8,Tasks!$H$4:$H$403,"Partially Completed") -> 7 | G8: =COUNTIFS(Tasks!$B$4:$B$403,$A8,Tasks!$H$4:$H$403,"") -> 0 | H8: =SUM(B8:G8) -> 22 | I8: =COUNTIFS(Tasks!$B$4:$B$403,$A8,Tasks!$K$4:$K$403,"<"&TODAY(),Tasks!$H$4:$H$403,"<>Complete") -> 22 | J8: =COUNTIFS(Tasks!$B$4:$B$403,$A8,Tasks!$I$4:$I$403,"") -> 0
A9: Semantic Communication | B9: =COUNTIFS(Tasks!$B$4:$B$403,$A9,Tasks!$H$4:$H$403,"Not Started") -> 14 | C9: =COUNTIFS(Tasks!$B$4:$B$403,$A9,Tasks!$H$4:$H$403,"In Progress") -> 0 | D9: =COUNTIFS(Tasks!$B$4:$B$403,$A9,Tasks!$H$4:$H$403,"Blocked") -> 0 | E9: =COUNTIFS(Tasks!$B$4:$B$403,$A9,Tasks!$H$4:$H$403,"Complete") -> 0 | F9: =COUNTIFS(Tasks!$B$4:$B$403,$A9,Tasks!$H$4:$H$403,"Partially Completed") -> 0 | G9: =COUNTIFS(Tasks!$B$4:$B$403,$A9,Tasks!$H$4:$H$403,"") -> 0 | H9: =SUM(B9:G9) -> 14 | I9: =COUNTIFS(Tasks!$B$4:$B$403,$A9,Tasks!$K$4:$K$403,"<"&TODAY(),Tasks!$H$4:$H$403,"<>Complete") -> 6 | J9: =COUNTIFS(Tasks!$B$4:$B$403,$A9,Tasks!$I$4:$I$403,"") -> 8
A10: Total | B10: =SUM(B5:B9) -> 91 | C10: =SUM(C5:C9) -> 11 | D10: =SUM(D5:D9) -> 1 | E10: =SUM(E5:E9) -> 0 | F10: =SUM(F5:F9) -> 9 | G10: =SUM(G5:G9) -> 7 | H10: =SUM(H5:H9) -> 119 | I10: =SUM(I5:I9) -> 42 | J10: =SUM(J5:J9) -> 16
A13: Owner (role) | B13: Person | C13: Not Started | D13: In Progress | E13: Blocked | F13: Complete | G13: Partially Completed | H13: No status | I13: Total | J13: Overdue | K13: Not scheduled
A14: Sensors & platform | B14: =IFERROR(INDEX(Lists!$B$4:$B$12,MATCH($A14,Lists!$A$4:$A$12,0)),"") -> TBD | C14: =COUNTIFS(Tasks!$F$4:$F$403,$A14,Tasks!$H$4:$H$403,"Not Started") -> 6 | D14: =COUNTIFS(Tasks!$F$4:$F$403,$A14,Tasks!$H$4:$H$403,"In Progress") -> 5 | E14: =COUNTIFS(Tasks!$F$4:$F$403,$A14,Tasks!$H$4:$H$403,"Blocked") -> 1 | F14: =COUNTIFS(Tasks!$F$4:$F$403,$A14,Tasks!$H$4:$H$403,"Complete") -> 0 | G14: =COUNTIFS(Tasks!$F$4:$F$403,$A14,Tasks!$H$4:$H$403,"Partially Completed") -> 0 | H14: =COUNTIFS(Tasks!$F$4:$F$403,$A14,Tasks!$H$4:$H$403,"") -> 5 | I14: =SUM(C14:H14) -> 17 | J14: =COUNTIFS(Tasks!$F$4:$F$403,$A14,Tasks!$K$4:$K$403,"<"&TODAY(),Tasks!$H$4:$H$403,"<>Complete") -> 3 | K14: =COUNTIFS(Tasks!$F$4:$F$403,$A14,Tasks!$I$4:$I$403,"") -> 5
A15: GS-SLAM | B15: =IFERROR(INDEX(Lists!$B$4:$B$12,MATCH($A15,Lists!$A$4:$A$12,0)),"") -> TBD | C15: =COUNTIFS(Tasks!$F$4:$F$403,$A15,Tasks!$H$4:$H$403,"Not Started") -> 8 | D15: =COUNTIFS(Tasks!$F$4:$F$403,$A15,Tasks!$H$4:$H$403,"In Progress") -> 0 | E15: =COUNTIFS(Tasks!$F$4:$F$403,$A15,Tasks!$H$4:$H$403,"Blocked") -> 0 | F15: =COUNTIFS(Tasks!$F$4:$F$403,$A15,Tasks!$H$4:$H$403,"Complete") -> 0 | G15: =COUNTIFS(Tasks!$F$4:$F$403,$A15,Tasks!$H$4:$H$403,"Partially Completed") -> 0 | H15: =COUNTIFS(Tasks!$F$4:$F$403,$A15,Tasks!$H$4:$H$403,"") -> 0 | I15: =SUM(C15:H15) -> 8 | J15: =COUNTIFS(Tasks!$F$4:$F$403,$A15,Tasks!$K$4:$K$403,"<"&TODAY(),Tasks!$H$4:$H$403,"<>Complete") -> 2 | K15: =COUNTIFS(Tasks!$F$4:$F$403,$A15,Tasks!$I$4:$I$403,"") -> 0
A16: Scene detection | B16: =IFERROR(INDEX(Lists!$B$4:$B$12,MATCH($A16,Lists!$A$4:$A$12,0)),"") -> TBD | C16: =COUNTIFS(Tasks!$F$4:$F$403,$A16,Tasks!$H$4:$H$403,"Not Started") -> 11 | D16: =COUNTIFS(Tasks!$F$4:$F$403,$A16,Tasks!$H$4:$H$403,"In Progress") -> 0 | E16: =COUNTIFS(Tasks!$F$4:$F$403,$A16,Tasks!$H$4:$H$403,"Blocked") -> 0 | F16: =COUNTIFS(Tasks!$F$4:$F$403,$A16,Tasks!$H$4:$H$403,"Complete") -> 0 | G16: =COUNTIFS(Tasks!$F$4:$F$403,$A16,Tasks!$H$4:$H$403,"Partially Completed") -> 0 | H16: =COUNTIFS(Tasks!$F$4:$F$403,$A16,Tasks!$H$4:$H$403,"") -> 0 | I16: =SUM(C16:H16) -> 11 | J16: =COUNTIFS(Tasks!$F$4:$F$403,$A16,Tasks!$K$4:$K$403,"<"&TODAY(),Tasks!$H$4:$H$403,"<>Complete") -> 4 | K16: =COUNTIFS(Tasks!$F$4:$F$403,$A16,Tasks!$I$4:$I$403,"") -> 0
A17: Isaac Sim | B17: =IFERROR(INDEX(Lists!$B$4:$B$12,MATCH($A17,Lists!$A$4:$A$12,0)),"") -> TBD | C17: =COUNTIFS(Tasks!$F$4:$F$403,$A17,Tasks!$H$4:$H$403,"Not Started") -> 8 | D17: =COUNTIFS(Tasks!$F$4:$F$403,$A17,Tasks!$H$4:$H$403,"In Progress") -> 0 | E17: =COUNTIFS(Tasks!$F$4:$F$403,$A17,Tasks!$H$4:$H$403,"Blocked") -> 0 | F17: =COUNTIFS(Tasks!$F$4:$F$403,$A17,Tasks!$H$4:$H$403,"Complete") -> 0 | G17: =COUNTIFS(Tasks!$F$4:$F$403,$A17,Tasks!$H$4:$H$403,"Partially Completed") -> 0 | H17: =COUNTIFS(Tasks!$F$4:$F$403,$A17,Tasks!$H$4:$H$403,"") -> 0 | I17: =SUM(C17:H17) -> 8 | J17: =COUNTIFS(Tasks!$F$4:$F$403,$A17,Tasks!$K$4:$K$403,"<"&TODAY(),Tasks!$H$4:$H$403,"<>Complete") -> 0 | K17: =COUNTIFS(Tasks!$F$4:$F$403,$A17,Tasks!$I$4:$I$403,"") -> 0
A18: Sionna RT | B18: =IFERROR(INDEX(Lists!$B$4:$B$12,MATCH($A18,Lists!$A$4:$A$12,0)),"") -> TBD | C18: =COUNTIFS(Tasks!$F$4:$F$403,$A18,Tasks!$H$4:$H$403,"Not Started") -> 4 | D18: =COUNTIFS(Tasks!$F$4:$F$403,$A18,Tasks!$H$4:$H$403,"In Progress") -> 0 | E18: =COUNTIFS(Tasks!$F$4:$F$403,$A18,Tasks!$H$4:$H$403,"Blocked") -> 0 | F18: =COUNTIFS(Tasks!$F$4:$F$403,$A18,Tasks!$H$4:$H$403,"Complete") -> 0 | G18: =COUNTIFS(Tasks!$F$4:$F$403,$A18,Tasks!$H$4:$H$403,"Partially Completed") -> 0 | H18: =COUNTIFS(Tasks!$F$4:$F$403,$A18,Tasks!$H$4:$H$403,"") -> 0 | I18: =SUM(C18:H18) -> 4 | J18: =COUNTIFS(Tasks!$F$4:$F$403,$A18,Tasks!$K$4:$K$403,"<"&TODAY(),Tasks!$H$4:$H$403,"<>Complete") -> 0 | K18: =COUNTIFS(Tasks!$F$4:$F$403,$A18,Tasks!$I$4:$I$403,"") -> 0
A19: SCooP dataset | B19: =IFERROR(INDEX(Lists!$B$4:$B$12,MATCH($A19,Lists!$A$4:$A$12,0)),"") -> TBD | C19: =COUNTIFS(Tasks!$F$4:$F$403,$A19,Tasks!$H$4:$H$403,"Not Started") -> 21 | D19: =COUNTIFS(Tasks!$F$4:$F$403,$A19,Tasks!$H$4:$H$403,"In Progress") -> 4 | E19: =COUNTIFS(Tasks!$F$4:$F$403,$A19,Tasks!$H$4:$H$403,"Blocked") -> 0 | F19: =COUNTIFS(Tasks!$F$4:$F$403,$A19,Tasks!$H$4:$H$403,"Complete") -> 0 | G19: =COUNTIFS(Tasks!$F$4:$F$403,$A19,Tasks!$H$4:$H$403,"Partially Completed") -> 2 | H19: =COUNTIFS(Tasks!$F$4:$F$403,$A19,Tasks!$H$4:$H$403,"") -> 2 | I19: =SUM(C19:H19) -> 29 | J19: =COUNTIFS(Tasks!$F$4:$F$403,$A19,Tasks!$K$4:$K$403,"<"&TODAY(),Tasks!$H$4:$H$403,"<>Complete") -> 5 | K19: =COUNTIFS(Tasks!$F$4:$F$403,$A19,Tasks!$I$4:$I$403,"") -> 3
A20: Dual-link comms | B20: =IFERROR(INDEX(Lists!$B$4:$B$12,MATCH($A20,Lists!$A$4:$A$12,0)),"") -> TBD | C20: =COUNTIFS(Tasks!$F$4:$F$403,$A20,Tasks!$H$4:$H$403,"Not Started") -> 13 | D20: =COUNTIFS(Tasks!$F$4:$F$403,$A20,Tasks!$H$4:$H$403,"In Progress") -> 2 | E20: =COUNTIFS(Tasks!$F$4:$F$403,$A20,Tasks!$H$4:$H$403,"Blocked") -> 0 | F20: =COUNTIFS(Tasks!$F$4:$F$403,$A20,Tasks!$H$4:$H$403,"Complete") -> 0 | G20: =COUNTIFS(Tasks!$F$4:$F$403,$A20,Tasks!$H$4:$H$403,"Partially Completed") -> 7 | H20: =COUNTIFS(Tasks!$F$4:$F$403,$A20,Tasks!$H$4:$H$403,"") -> 0 | I20: =SUM(C20:H20) -> 22 | J20: =COUNTIFS(Tasks!$F$4:$F$403,$A20,Tasks!$K$4:$K$403,"<"&TODAY(),Tasks!$H$4:$H$403,"<>Complete") -> 22 | K20: =COUNTIFS(Tasks!$F$4:$F$403,$A20,Tasks!$I$4:$I$403,"") -> 0
A21: Semantic comms | B21: =IFERROR(INDEX(Lists!$B$4:$B$12,MATCH($A21,Lists!$A$4:$A$12,0)),"") -> TBD | C21: =COUNTIFS(Tasks!$F$4:$F$403,$A21,Tasks!$H$4:$H$403,"Not Started") -> 14 | D21: =COUNTIFS(Tasks!$F$4:$F$403,$A21,Tasks!$H$4:$H$403,"In Progress") -> 0 | E21: =COUNTIFS(Tasks!$F$4:$F$403,$A21,Tasks!$H$4:$H$403,"Blocked") -> 0 | F21: =COUNTIFS(Tasks!$F$4:$F$403,$A21,Tasks!$H$4:$H$403,"Complete") -> 0 | G21: =COUNTIFS(Tasks!$F$4:$F$403,$A21,Tasks!$H$4:$H$403,"Partially Completed") -> 0 | H21: =COUNTIFS(Tasks!$F$4:$F$403,$A21,Tasks!$H$4:$H$403,"") -> 0 | I21: =SUM(C21:H21) -> 14 | J21: =COUNTIFS(Tasks!$F$4:$F$403,$A21,Tasks!$K$4:$K$403,"<"&TODAY(),Tasks!$H$4:$H$403,"<>Complete") -> 6 | K21: =COUNTIFS(Tasks!$F$4:$F$403,$A21,Tasks!$I$4:$I$403,"") -> 8
A22: All (integration) | B22: =IFERROR(INDEX(Lists!$B$4:$B$12,MATCH($A22,Lists!$A$4:$A$12,0)),"") -> TBD | C22: =COUNTIFS(Tasks!$F$4:$F$403,$A22,Tasks!$H$4:$H$403,"Not Started") -> 6 | D22: =COUNTIFS(Tasks!$F$4:$F$403,$A22,Tasks!$H$4:$H$403,"In Progress") -> 0 | E22: =COUNTIFS(Tasks!$F$4:$F$403,$A22,Tasks!$H$4:$H$403,"Blocked") -> 0 | F22: =COUNTIFS(Tasks!$F$4:$F$403,$A22,Tasks!$H$4:$H$403,"Complete") -> 0 | G22: =COUNTIFS(Tasks!$F$4:$F$403,$A22,Tasks!$H$4:$H$403,"Partially Completed") -> 0 | H22: =COUNTIFS(Tasks!$F$4:$F$403,$A22,Tasks!$H$4:$H$403,"") -> 0 | I22: =SUM(C22:H22) -> 6 | J22: =COUNTIFS(Tasks!$F$4:$F$403,$A22,Tasks!$K$4:$K$403,"<"&TODAY(),Tasks!$H$4:$H$403,"<>Complete") -> 0 | K22: =COUNTIFS(Tasks!$F$4:$F$403,$A22,Tasks!$I$4:$I$403,"") -> 0
A23: Total | C23: =SUM(C14:C22) -> 91 | D23: =SUM(D14:D22) -> 11 | E23: =SUM(E14:E22) -> 1 | F23: =SUM(F14:F22) -> 0 | G23: =SUM(G14:G22) -> 9 | H23: =SUM(H14:H22) -> 7 | I23: =SUM(I14:I22) -> 119 | J23: =SUM(J14:J22) -> 42 | K23: =SUM(K14:K22) -> 16
A26: Problems | B26: Open | C26: Investigating | D26: Resolved | E26: Won't fix | F26: Still open
A27: Blocker | B27: =COUNTIFS(Problems!$F$4:$F$203,$A27,Problems!$G$4:$G$203,"Open") -> 1 | C27: =COUNTIFS(Problems!$F$4:$F$203,$A27,Problems!$G$4:$G$203,"Investigating") -> 0 | D27: =COUNTIFS(Problems!$F$4:$F$203,$A27,Problems!$G$4:$G$203,"Resolved") -> 0 | E27: =COUNTIFS(Problems!$F$4:$F$203,$A27,Problems!$G$4:$G$203,"Won't fix") -> 0 | F27: =B27+C27 -> 1
A28: Major | B28: =COUNTIFS(Problems!$F$4:$F$203,$A28,Problems!$G$4:$G$203,"Open") -> 2 | C28: =COUNTIFS(Problems!$F$4:$F$203,$A28,Problems!$G$4:$G$203,"Investigating") -> 3 | D28: =COUNTIFS(Problems!$F$4:$F$203,$A28,Problems!$G$4:$G$203,"Resolved") -> 0 | E28: =COUNTIFS(Problems!$F$4:$F$203,$A28,Problems!$G$4:$G$203,"Won't fix") -> 0 | F28: =B28+C28 -> 5
A29: Minor | B29: =COUNTIFS(Problems!$F$4:$F$203,$A29,Problems!$G$4:$G$203,"Open") -> 4 | C29: =COUNTIFS(Problems!$F$4:$F$203,$A29,Problems!$G$4:$G$203,"Investigating") -> 0 | D29: =COUNTIFS(Problems!$F$4:$F$203,$A29,Problems!$G$4:$G$203,"Resolved") -> 0 | E29: =COUNTIFS(Problems!$F$4:$F$203,$A29,Problems!$G$4:$G$203,"Won't fix") -> 0 | F29: =B29+C29 -> 4
A32: Interfaces | B32: Count
A33: Not defined | B33: =COUNTIF(Interfaces!$J$4:$J$103,$A33) -> 14
A34: Defined | B34: =COUNTIF(Interfaces!$J$4:$J$103,$A34) -> 0
A35: Implemented | B35: =COUNTIF(Interfaces!$J$4:$J$103,$A35) -> 0
A36: Tested | B36: =COUNTIF(Interfaces!$J$4:$J$103,$A36) -> 0

Sheet Tasks
A1: Tasks
A2: One row per task. Start + Weeks drive the Gantt sheet. Grey italic columns are formulas.
A3: ID | B3: Goal | C3: Component | D3: Task | E3: Detail | F3: Owner (role) | G3: Person | H3: Status | I3: Start | J3: Weeks | K3: End | L3: Depends on | M3: Done when | N3: Link | O3: Notes | P3: Old tracker ref
A4: TB-1 | B4: Shared SCooP testbed | C4: Testbed | D4: Hardware inventory & specs | E4: mobile_1, mobile_2, infra masts, sniffer: what is mounted where. | F4: Sensors & platform | G4: =IF($F4="","",IFERROR(INDEX(Lists!$B$4:$B$12,MATCH($F4,Lists!$A$4:$A$12,0)),"")) -> TBD | H4: Not Started | I4: 46307 | J4: 2 | K4: =IF(OR($I4="",$J4=""),"",$I4+7*$J4-3) -> 46318 | M4: Number of infra masts fixed; cascade radar and mobile_2 radar/Wi-Fi specs confirmed (paper sensors table complete)
A5: TB-2 | B5: Shared SCooP testbed | C5: Testbed | D5: Sensor calibration (all units) | E5: Spatial and temporal calibration across all sensors; verify the TF chain (map -> odom -> zed_camera_center). | F5: Sensors & platform | G5: =IF($F5="","",IFERROR(INDEX(Lists!$B$4:$B$12,MATCH($F5,Lists!$A$4:$A$12,0)),"")) -> TBD | H5: In Progress | I5: 46195 | J5: 2 | K5: =IF(OR($I5="",$J5=""),"",$I5+7*$J5-3) -> 46206 | M5: Calibration table in the paper filled; residual per sensor pair recorded | P5: Dataset Collection 1
A6: TB-2.1 | B6: Shared SCooP testbed | C6: Testbed | D6: Sensor Calibration (LiDAR-Camera, LiDAR-IMU, Camera-Radar, Intrinsics, Realsense-Zed, Mobile-Infra Extrinsics) | E6: Spatial calibration across all sensor pairs. | F6: Sensors & platform | G6: =IF($F6="","",IFERROR(INDEX(Lists!$B$4:$B$12,MATCH($F6,Lists!$A$4:$A$12,0)),"")) -> TBD | H6: In Progress | I6: 46195 | J6: 2 | K6: =IF(OR($I6="",$J6=""),"",$I6+7*$J6-3) -> 46206 | P6: Dataset Collection 1.1
A7: TB-2.2 | B7: Shared SCooP testbed | C7: Testbed | D7: Calibration: LiDAR - Camera | E7: From the old tracker's Sheet1 calibration list. | F7: Sensors & platform | G7: =IF($F7="","",IFERROR(INDEX(Lists!$B$4:$B$12,MATCH($F7,Lists!$A$4:$A$12,0)),"")) -> TBD | K7: =IF(OR($I7="",$J7=""),"",$I7+7*$J7-3) | O7: Status not recorded in the old file | P7: Old Sheet1 'calibration'
A8: TB-2.3 | B8: Shared SCooP testbed | C8: Testbed | D8: Calibration: LiDAR - IMU | E8: From the old tracker's Sheet1 calibration list. | F8: Sensors & platform | G8: =IF($F8="","",IFERROR(INDEX(Lists!$B$4:$B$12,MATCH($F8,Lists!$A$4:$A$12,0)),"")) -> TBD | K8: =IF(OR($I8="",$J8=""),"",$I8+7*$J8-3) | O8: Status not recorded in the old file | P8: Old Sheet1 'calibration'
A9: TB-2.4 | B9: Shared SCooP testbed | C9: Testbed | D9: Calibration: RealSense - ZED | E9: From the old tracker's Sheet1 calibration list. | F9: Sensors & platform | G9: =IF($F9="","",IFERROR(INDEX(Lists!$B$4:$B$12,MATCH($F9,Lists!$A$4:$A$12,0)),"")) -> TBD | K9: =IF(OR($I9="",$J9=""),"",$I9+7*$J9-3) | O9: Status not recorded in the old file | P9: Old Sheet1 'calibration'
A10: TB-2.5 | B10: Shared SCooP testbed | C10: Testbed | D10: Calibration: ZED - Arducam | E10: From the old tracker's Sheet1 calibration list. | F10: Sensors & platform | G10: =IF($F10="","",IFERROR(INDEX(Lists!$B$4:$B$12,MATCH($F10,Lists!$A$4:$A$12,0)),"")) -> TBD | K10: =IF(OR($I10="",$J10=""),"",$I10+7*$J10-3) | O10: Status not recorded in the old file | P10: Old Sheet1 'calibration'
A11: TB-2.6 | B11: Shared SCooP testbed | C11: Testbed | D11: Calibration: Radars - ZED | E11: From the old tracker's Sheet1 calibration list. | F11: Sensors & platform | G11: =IF($F11="","",IFERROR(INDEX(Lists!$B$4:$B$12,MATCH($F11,Lists!$A$4:$A$12,0)),"")) -> TBD | K11: =IF(OR($I11="",$J11=""),"",$I11+7*$J11-3) | O11: Status not recorded in the old file | P11: Old Sheet1 'calibration'
A12: TB-3 | B12: Shared SCooP testbed | C12: Testbed | D12: Time sync & TF chain | E12: Confirm TF chain resolves; sync clocks via UTC pivot. | F12: Sensors & platform | G12: =IF($F12="","",IFERROR(INDEX(Lists!$B$4:$B$12,MATCH($F12,Lists!$A$4:$A$12,0)),"")) -> TBD | H12: In Progress | I12: 46202 | J12: 1 | K12: =IF(OR($I12="",$J12=""),"",$I12+7*$J12-3) -> 46206 | M12: Sniffer NTP bias measured; NTP checked over >= 3 passes; per-sensor transport latency measured; TF chain resolves | P12: Dataset Collection 1.2
A13: TB-4 | B13: Shared SCooP testbed | C13: Testbed | D13: Wi-Fi & comms logging | E13: AP ch149 VHT-80, wifi/status, iperf3, ping, chrony, Nexmon CSI. | F13: Sensors & platform | G13: =IF($F13="","",IFERROR(INDEX(Lists!$B$4:$B$12,MATCH($F13,Lists!$A$4:$A$12,0)),"")) -> TBD | H13: In Progress | I13: 46307 | J13: 2 | K13: =IF(OR($I13="",$J13=""),"",$I13+7*$J13-3) -> 46318 | M13: Pre-recording check passes on every node
A14: TB-5 | B14: Shared SCooP testbed | C14: Testbed | D14: Recording tooling fixes | E14: Record mobile_2's on-board VSLAM; record mobile_2 depth/IMU/IR in survey mode. | F14: Sensors & platform | G14: =IF($F14="","",IFERROR(INDEX(Lists!$B$4:$B$12,MATCH($F14,Lists!$A$4:$A$12,0)),"")) -> TBD | H14: Not Started | I14: 46307 | J14: 2 | K14: =IF(OR($I14="",$J14=""),"",$I14+7*$J14-3) -> 46318 | L14: TB-4 | M14: A test pass records every topic listed in record.yaml
A15: G2-DS-1 | B15: G2 SCooP dataset & paper | C15: SCooP dataset | D15: Recording campaign | E15: All sites x pass types (mapping, survey, coop, contention). Site 1 (MIRC) recorded 2026-09-24. | F15: SCooP dataset | G15: =IF($F15="","",IFERROR(INDEX(Lists!$B$4:$B$12,MATCH($F15,Lists!$A$4:$A$12,0)),"")) -> TBD | H15: Partially Completed | I15: 46314 | J15: 6 | K15: =IF(OR($I15="",$J15=""),"",$I15+7*$J15-3) -> 46353 | L15: TB-2, TB-3, TB-5 | M15: Sites 2 and 3 recorded, all four pass types per site | O15: Only Cameras and LiDAR mainly for calibration accuracy validation | P15: Dataset Collection 2 | tag Dataset #1
A16: G2-DS-1.1 | B16: G2 SCooP dataset & paper | C16: SCooP dataset | D16: Indoor Trajectory Sessions | E16: Planned indoor routes and formations across both robots. | F16: SCooP dataset | G16: =IF($F16="","",IFERROR(INDEX(Lists!$B$4:$B$12,MATCH($F16,Lists!$A$4:$A$12,0)),"")) -> TBD | H16: Partially Completed | I16: 46202 | J16: 1 | K16: =IF(OR($I16="",$J16=""),"",$I16+7*$J16-3) -> 46206 | O16: 2 different datasets → detect change (in validation) | P16: Dataset Collection 2.1
A17: G2-DS-1.2 | B17: G2 SCooP dataset & paper | C17: SCooP dataset | D17: Outdoor Trajectory Sessions | E17: Planned outdoor routes, including GPS-denied test zones. | F17: SCooP dataset | G17: =IF($F17="","",IFERROR(INDEX(Lists!$B$4:$B$12,MATCH($F17,Lists!$A$4:$A$12,0)),"")) -> TBD | H17: Not Started | K17: =IF(OR($I17="",$J17=""),"",$I17+7*$J17-3) | O17: Old tracker: red across W1-W10 (read as not scheduled) | P17: Dataset Collection 2.2
A18: G2-DS-1.3 | B18: G2 SCooP dataset & paper | C18: SCooP dataset | D18: Record sites 2 and 3 | E18: Mapping, survey, coop, contention passes per site. | F18: SCooP dataset | G18: =IF($F18="","",IFERROR(INDEX(Lists!$B$4:$B$12,MATCH($F18,Lists!$A$4:$A$12,0)),"")) -> TBD | H18: Not Started | I18: 46321 | J18: 4 | K18: =IF(OR($I18="",$J18=""),"",$I18+7*$J18-3) -> 46346 | L18: TB-5
A19: G2-DS-1.4 | B19: G2 SCooP dataset & paper | C19: SCooP dataset | D19: Calibration rosbag | E19: Stop at several points where camera and LiDAR see the same scene (LiDAR, radar, ZED; Arducam; RealSense). | F19: SCooP dataset | G19: =IF($F19="","",IFERROR(INDEX(Lists!$B$4:$B$12,MATCH($F19,Lists!$A$4:$A$12,0)),"")) -> TBD | I19: 46314 | J19: 1 | K19: =IF(OR($I19="",$J19=""),"",$I19+7*$J19-3) -> 46318 | O19: Status not recorded in the old file | P19: Old Sheet1 'To record' 2
A20: G2-DS-1.5 | B20: G2 SCooP dataset & paper | C20: SCooP dataset | D20: Short test recordings | E20: Distance from object, occlusion, object at image edge (LiDAR, radar, ZED; Arducam; RealSense). | F20: SCooP dataset | G20: =IF($F20="","",IFERROR(INDEX(Lists!$B$4:$B$12,MATCH($F20,Lists!$A$4:$A$12,0)),"")) -> TBD | I20: 46314 | J20: 1 | K20: =IF(OR($I20="",$J20=""),"",$I20+7*$J20-3) -> 46318 | O20: Status not recorded in the old file | P20: Old Sheet1 'To record' 2
A21: G2-DS-2 | B21: G2 SCooP dataset & paper | C21: SCooP dataset | D21: Per-pass processing | E21: Decode Ouster, retime, GLIM, ZED SVO->bag, offline cuVSLAM for mobile_2, merge + check against record.yaml. | F21: SCooP dataset | G21: =IF($F21="","",IFERROR(INDEX(Lists!$B$4:$B$12,MATCH($F21,Lists!$A$4:$A$12,0)),"")) -> TBD | H21: In Progress | I21: 46307 | J21: 10 | K21: =IF(OR($I21="",$J21=""),"",$I21+7*$J21-3) -> 46374 | M21: Every recorded pass processed and merged; bag_check clean | O21: Done for the 2026-09-24 passes; rerun per new pass | P21: Dataset Collection 3 | tag Dataset #2
A22: G2-DS-2.1 | B22: G2 SCooP dataset & paper | C22: SCooP dataset | D22: Merging Sensor Data | E22: Merge all recorded sensor data and transforms | F22: SCooP dataset | G22: =IF($F22="","",IFERROR(INDEX(Lists!$B$4:$B$12,MATCH($F22,Lists!$A$4:$A$12,0)),"")) -> TBD | H22: In Progress | I22: 46202 | J22: 1 | K22: =IF(OR($I22="",$J22=""),"",$I22+7*$J22-3) -> 46206 | P22: Dataset Collection 2.3
A23: G2-DS-2.2 | B23: G2 SCooP dataset & paper | C23: SCooP dataset | D23: Timestamp Alignment Post-Processing | E23: Align all recorded streams to the UTC pivot reference. | F23: SCooP dataset | G23: =IF($F23="","",IFERROR(INDEX(Lists!$B$4:$B$12,MATCH($F23,Lists!$A$4:$A$12,0)),"")) -> TBD | H23: Not Started | I23: 46202 | J23: 1 | K23: =IF(OR($I23="",$J23=""),"",$I23+7*$J23-3) -> 46206 | P23: Dataset Collection 3.1
A24: G2-DS-3 | B24: G2 SCooP dataset & paper | C24: SCooP dataset | D24: Reference maps & board networks per site | E24: Map stages 01-02; ChArUco board network. | F24: SCooP dataset | G24: =IF($F24="","",IFERROR(INDEX(Lists!$B$4:$B$12,MATCH($F24,Lists!$A$4:$A$12,0)),"")) -> TBD | H24: In Progress | I24: 46307 | J24: 8 | K24: =IF(OR($I24="",$J24=""),"",$I24+7*$J24-3) -> 46360 | M24: Map + boards per site; wall/floor thickness reported | O24: Done for site 1 mapping_A (7.4 / 2.6 cm)
A25: G2-DS-3.1 | B25: G2 SCooP dataset & paper | C25: SCooP dataset | D25: Localization and Mapping | E25: Pointcloud Mapping using LiDAR (LiDAR-SLAM) and Camera (V-SLAM) | F25: SCooP dataset | G25: =IF($F25="","",IFERROR(INDEX(Lists!$B$4:$B$12,MATCH($F25,Lists!$A$4:$A$12,0)),"")) -> TBD | H25: Not Started | I25: 46202 | J25: 1 | K25: =IF(OR($I25="",$J25=""),"",$I25+7*$J25-3) -> 46206 | P25: Dataset Collection 3.2
A26: G2-DS-3.2 | B26: G2 SCooP dataset & paper | C26: SCooP dataset | D26: Mesh Conversion | E26: Converting pointcloud data to watertight mesh/cuboids | F26: SCooP dataset | G26: =IF($F26="","",IFERROR(INDEX(Lists!$B$4:$B$12,MATCH($F26,Lists!$A$4:$A$12,0)),"")) -> TBD | H26: Not Started | I26: 46209 | J26: 2 | K26: =IF(OR($I26="",$J26=""),"",$I26+7*$J26-3) -> 46220 | O26: Varying object resolution → zoom in, zoom out | P26: Dataset Collection 3.3
A27: G2-DS-4 | B27: G2 SCooP dataset & paper | C27: SCooP dataset | D27: Reference poses (map stages 03-10) | E27: Boards init, reference trajectory (LiDAR ICP; depth_track/PGO for mobile_2), anchor, cut, cameras, TFs, cloud, poses. | F27: SCooP dataset | G27: =IF($F27="","",IFERROR(INDEX(Lists!$B$4:$B$12,MATCH($F27,Lists!$A$4:$A$12,0)),"")) -> TBD | H27: In Progress | I27: 46307 | J27: 6 | K27: =IF(OR($I27="",$J27=""),"",$I27+7*$J27-3) -> 46346 | L27: G2-DS-3 | M27: Every robot in every sequence has a reference trajectory | O27: Current: coop_2 mobile_2 track (P-001)
A28: G2-DS-5 | B28: G2 SCooP dataset & paper | C28: SCooP dataset | D28: Ground-truth validation | E28: Control distances, held-out boards, cross-robot, cross-session. | F28: SCooP dataset | G28: =IF($F28="","",IFERROR(INDEX(Lists!$B$4:$B$12,MATCH($F28,Lists!$A$4:$A$12,0)),"")) -> TBD | H28: Not Started | I28: 46342 | J28: 3 | K28: =IF(OR($I28="",$J28=""),"",$I28+7*$J28-3) -> 46360 | L28: G2-DS-4 | M28: Paper GT table has no '--' cells
A29: G2-DS-6 | B29: G2 SCooP dataset & paper | C29: SCooP dataset | D29: Annotations | E29: Boxes, per-point labels, masks; decide the keyframe rate. No pipeline code yet. | F29: SCooP dataset | G29: =IF($F29="","",IFERROR(INDEX(Lists!$B$4:$B$12,MATCH($F29,Lists!$A$4:$A$12,0)),"")) -> TBD | H29: Not Started | I29: 46335 | J29: 7 | K29: =IF(OR($I29="",$J29=""),"",$I29+7*$J29-3) -> 46381 | L29: G2-DS-4 | M29: Annotation set + statistics for every sequence | P29: Dataset Collection 3.4
A30: G2-DS-6.1 | B30: G2 SCooP dataset & paper | C30: SCooP dataset | D30: Label QA (Coverage & Class Balance) | E30: Spot-check annotation quality and scenario/class coverage. | F30: SCooP dataset | G30: =IF($F30="","",IFERROR(INDEX(Lists!$B$4:$B$12,MATCH($F30,Lists!$A$4:$A$12,0)),"")) -> TBD | H30: Not Started | K30: =IF(OR($I30="",$J30=""),"",$I30+7*$J30-3) | O30: Old tracker: red across W1-W10 (read as not scheduled) | P30: Dataset Collection 4.1
A31: G2-DS-7 | B31: G2 SCooP dataset & paper | C31: SCooP dataset | D31: Collaboration geometry & comm ground truth | E31: Overlap, visibility, beta, C, Fresnel clearance; comms tables; channel replay. | F31: SCooP dataset | G31: =IF($F31="","",IFERROR(INDEX(Lists!$B$4:$B$12,MATCH($F31,Lists!$A$4:$A$12,0)),"")) -> TBD | H31: Not Started | I31: 46349 | J31: 5 | K31: =IF(OR($I31="",$J31=""),"",$I31+7*$J31-3) -> 46381 | L31: G2-DS-4, TB-4 | M31: Per-frame geometry + link files for every coop sequence
A32: G2-DS-8 | B32: G2 SCooP dataset & paper | C32: SCooP dataset | D32: Release | E32: Raw MCAP layout, OPV2V-style extracted format, devkit, license/DOI/hosting. | F32: SCooP dataset | G32: =IF($F32="","",IFERROR(INDEX(Lists!$B$4:$B$12,MATCH($F32,Lists!$A$4:$A$12,0)),"")) -> TBD | H32: Not Started | I32: 46384 | J32: 5 | K32: =IF(OR($I32="",$J32=""),"",$I32+7*$J32-3) -> 46416 | L32: G2-DS-5, G2-DS-6, G2-DS-7 | M32: Versioned release online with DOI; devkit examples run | O32: Old tracker: red across W1-W10 (read as not scheduled) | P32: Dataset Collection 4 | tag Dataset #3
A33: G2-DS-8.1 | B33: G2 SCooP dataset & paper | C33: SCooP dataset | D33: Dataset Packaging & Documentation | E33: Assemble the final versioned dataset release. | F33: SCooP dataset | G33: =IF($F33="","",IFERROR(INDEX(Lists!$B$4:$B$12,MATCH($F33,Lists!$A$4:$A$12,0)),"")) -> TBD | H33: Not Started | K33: =IF(OR($I33="",$J33=""),"",$I33+7*$J33-3) | O33: Old tracker: red across W1-W10 (read as not scheduled) | P33: Dataset Collection 4.2
A34: G2-DS-8.2 | B34: G2 SCooP dataset & paper | C34: SCooP dataset | D34: Devkit | E34: Readers, calib/clock API, projection, geometry, channel replay, evaluation. | F34: SCooP dataset | G34: =IF($F34="","",IFERROR(INDEX(Lists!$B$4:$B$12,MATCH($F34,Lists!$A$4:$A$12,0)),"")) -> TBD | H34: Not Started | I34: 46384 | J34: 4 | K34: =IF(OR($I34="",$J34=""),"",$I34+7*$J34-3) -> 46409
A35: G2-DS-8.3 | B35: G2 SCooP dataset & paper | C35: SCooP dataset | D35: License, DOI, hosting | F35: SCooP dataset | G35: =IF($F35="","",IFERROR(INDEX(Lists!$B$4:$B$12,MATCH($F35,Lists!$A$4:$A$12,0)),"")) -> TBD | H35: Not Started | I35: 46398 | J35: 2 | K35: =IF(OR($I35="",$J35=""),"",$I35+7*$J35-3) -> 46409
A36: G2-BP-A | B36: G2 SCooP dataset & paper | C36: SCooP paper & benchmarks | D36: Ground-truth numbers (RESULTS_PLAN A0) | E36: Control distances, held-out board residuals, box-fit fraction, sniffer bias. | F36: SCooP dataset | G36: =IF($F36="","",IFERROR(INDEX(Lists!$B$4:$B$12,MATCH($F36,Lists!$A$4:$A$12,0)),"")) -> TBD | H36: Not Started | I36: 46314 | J36: 3 | K36: =IF(OR($I36="",$J36=""),"",$I36+7*$J36-3) -> 46332 | L36: G2-DS-4
A37: G2-BP-B | B37: G2 SCooP dataset & paper | C37: SCooP paper & benchmarks | D37: Inventory & statistics tables (B) | E37: Sessions and sequence tables, annotation statistics. | F37: SCooP dataset | G37: =IF($F37="","",IFERROR(INDEX(Lists!$B$4:$B$12,MATCH($F37,Lists!$A$4:$A$12,0)),"")) -> TBD | H37: Not Started | I37: 46342 | J37: 3 | K37: =IF(OR($I37="",$J37=""),"",$I37+7*$J37-3) -> 46360 | L37: G2-DS-1
A38: G2-BP-C | B38: G2 SCooP dataset & paper | C38: SCooP paper & benchmarks | D38: Geometry validation (C) | E38: Clearance vs RSSI, co-visibility vs evidence. | F38: SCooP dataset | G38: =IF($F38="","",IFERROR(INDEX(Lists!$B$4:$B$12,MATCH($F38,Lists!$A$4:$A$12,0)),"")) -> TBD | H38: Not Started | I38: 46363 | J38: 3 | K38: =IF(OR($I38="",$J38=""),"",$I38+7*$J38-3) -> 46381 | L38: G2-DS-7
A39: G2-BP-D | B39: G2 SCooP dataset & paper | C39: SCooP paper & benchmarks | D39: T2 collaborative perception under 3 channels (D) | E39: Port the OpenCOOD harness; early, late, Where2comm minimum. | F39: SCooP dataset | G39: =IF($F39="","",IFERROR(INDEX(Lists!$B$4:$B$12,MATCH($F39,Lists!$A$4:$A$12,0)),"")) -> TBD | H39: Not Started | I39: 46363 | J39: 5 | K39: =IF(OR($I39="",$J39=""),"",$I39+7*$J39-3) -> 46395 | L39: G2-DS-6, G2-DS-7
A40: G2-BP-E | B40: G2 SCooP dataset & paper | C40: SCooP paper & benchmarks | D40: T1 collaborative SLAM (E) | E40: Swarm-SLAM minimum; DiSCo, COVINS-G, Kimera/Hydra-Multi stretch. | F40: SCooP dataset | G40: =IF($F40="","",IFERROR(INDEX(Lists!$B$4:$B$12,MATCH($F40,Lists!$A$4:$A$12,0)),"")) -> TBD | H40: Not Started | I40: 46363 | J40: 5 | K40: =IF(OR($I40="",$J40=""),"",$I40+7*$J40-3) -> 46395 | L40: G2-DS-4
...

Sheet Gantt
A1: Gantt
A2: Gantt starts (Monday): | C2: 46195 | E2: Today: | F2: =TODAY() -> 46302
A4: ID | B4: Task | C4: Owner | D4: Status | E4: Start | F4: End | G4: =$C$2+7*0 -> 46195 | H4: =$C$2+7*1 -> 46202 | I4: =$C$2+7*2 -> 46209 | J4: =$C$2+7*3 -> 46216 | K4: =$C$2+7*4 -> 46223 | L4: =$C$2+7*5 -> 46230 | M4: =$C$2+7*6 -> 46237 | N4: =$C$2+7*7 -> 46244 | O4: =$C$2+7*8 -> 46251 | P4: =$C$2+7*9 -> 46258 | Q4: =$C$2+7*10 -> 46265 | R4: =$C$2+7*11 -> 46272 | S4: =$C$2+7*12 -> 46279 | T4: =$C$2+7*13 -> 46286 | U4: =$C$2+7*14 -> 46293 | V4: =$C$2+7*15 -> 46300 | W4: =$C$2+7*16 -> 46307 | X4: =$C$2+7*17 -> 46314 | Y4: =$C$2+7*18 -> 46321 | Z4: =$C$2+7*19 -> 46328 | AA4: =$C$2+7*20 -> 46335 | AB4: =$C$2+7*21 -> 46342 | AC4: =$C$2+7*22 -> 46349 | AD4: =$C$2+7*23 -> 46356 | AE4: =$C$2+7*24 -> 46363 | AF4: =$C$2+7*25 -> 46370 | AG4: =$C$2+7*26 -> 46377 | AH4: =$C$2+7*27 -> 46384 | AI4: =$C$2+7*28 -> 46391 | AJ4: =$C$2+7*29 -> 46398 | AK4: =$C$2+7*30 -> 46405 | AL4: =$C$2+7*31 -> 46412 | AM4: =$C$2+7*32 -> 46419 | AN4: =$C$2+7*33 -> 46426 | AO4: =$C$2+7*34 -> 46433 | AP4: =$C$2+7*35 -> 46440 | AQ4: =$C$2+7*36 -> 46447 | AR4: =$C$2+7*37 -> 46454 | AS4: =$C$2+7*38 -> 46461 | AT4: =$C$2+7*39 -> 46468 | AU4: =$C$2+7*40 -> 46475 | AV4: =$C$2+7*41 -> 46482 | AW4: =$C$2+7*42 -> 46489 | AX4: =$C$2+7*43 -> 46496 | BA4: Legend
A5: =IF(INDEX(Tasks!$A:$A,ROW()-1)="","",INDEX(Tasks!$A:$A,ROW()-1)) -> TB-1 | B5: =IF(INDEX(Tasks!$A:$A,ROW()-1)="","",IF(ISERROR(FIND(".",INDEX(Tasks!$A:$A,ROW()-1))),""," ")&INDEX(Tasks!$D:$D,ROW()-1)) -> Hardware inventory & specs | C5: =IF(INDEX(Tasks!$G:$G,ROW()-1)="","",INDEX(Tasks!$G:$G,ROW()-1)) -> TBD | D5: =IF(INDEX(Tasks!$H:$H,ROW()-1)="","",INDEX(Tasks!$H:$H,ROW()-1)) -> Not Started | E5: =IF(INDEX(Tasks!$I:$I,ROW()-1)="","",INDEX(Tasks!$I:$I,ROW()-1)) -> 46307 | F5: =IF(INDEX(Tasks!$K:$K,ROW()-1)="","",INDEX(Tasks!$K:$K,ROW()-1)) -> 46318 | BA5: Complete
A6: =IF(INDEX(Tasks!$A:$A,ROW()-1)="","",INDEX(Tasks!$A:$A,ROW()-1)) -> TB-2 | B6: =IF(INDEX(Tasks!$A:$A,ROW()-1)="","",IF(ISERROR(FIND(".",INDEX(Tasks!$A:$A,ROW()-1))),""," ")&INDEX(Tasks!$D:$D,ROW()-1)) -> Sensor calibration (all units) | C6: =IF(INDEX(Tasks!$G:$G,ROW()-1)="","",INDEX(Tasks!$G:$G,ROW()-1)) -> TBD | D6: =IF(INDEX(Tasks!$H:$H,ROW()-1)="","",INDEX(Tasks!$H:$H,ROW()-1)) -> In Progress | E6: =IF(INDEX(Tasks!$I:$I,ROW()-1)="","",INDEX(Tasks!$I:$I,ROW()-1)) -> 46195 | F6: =IF(INDEX(Tasks!$K:$K,ROW()-1)="","",INDEX(Tasks!$K:$K,ROW()-1)) -> 46206 | BA6: In Progress
A7: =IF(INDEX(Tasks!$A:$A,ROW()-1)="","",INDEX(Tasks!$A:$A,ROW()-1)) -> TB-2.1 | B7: =IF(INDEX(Tasks!$A:$A,ROW()-1)="","",IF(ISERROR(FIND(".",INDEX(Tasks!$A:$A,ROW()-1))),""," ")&INDEX(Tasks!$D:$D,ROW()-1)) -> Sensor Calibration (LiDAR-Camera, LiDAR-IMU, Camera-Radar, Intrinsics, Realsense-Zed, Mobile-Infra Extrinsics) | C7: =IF(INDEX(Tasks!$G:$G,ROW()-1)="","",INDEX(Tasks!$G:$G,ROW()-1)) -> TBD | D7: =IF(INDEX(Tasks!$H:$H,ROW()-1)="","",INDEX(Tasks!$H:$H,ROW()-1)) -> In Progress | E7: =IF(INDEX(Tasks!$I:$I,ROW()-1)="","",INDEX(Tasks!$I:$I,ROW()-1)) -> 46195 | F7: =IF(INDEX(Tasks!$K:$K,ROW()-1)="","",INDEX(Tasks!$K:$K,ROW()-1)) -> 46206 | BA7: Partially Completed
A8: =IF(INDEX(Tasks!$A:$A,ROW()-1)="","",INDEX(Tasks!$A:$A,ROW()-1)) -> TB-2.2 | B8: =IF(INDEX(Tasks!$A:$A,ROW()-1)="","",IF(ISERROR(FIND(".",INDEX(Tasks!$A:$A,ROW()-1))),""," ")&INDEX(Tasks!$D:$D,ROW()-1)) -> Calibration: LiDAR - Camera | C8: =IF(INDEX(Tasks!$G:$G,ROW()-1)="","",INDEX(Tasks!$G:$G,ROW()-1)) -> TBD | D8: =IF(INDEX(Tasks!$H:$H,ROW()-1)="","",INDEX(Tasks!$H:$H,ROW()-1)) | E8: =IF(INDEX(Tasks!$I:$I,ROW()-1)="","",INDEX(Tasks!$I:$I,ROW()-1)) | F8: =IF(INDEX(Tasks!$K:$K,ROW()-1)="","",INDEX(Tasks!$K:$K,ROW()-1)) | BA8: Blocked
A9: =IF(INDEX(Tasks!$A:$A,ROW()-1)="","",INDEX(Tasks!$A:$A,ROW()-1)) -> TB-2.3 | B9: =IF(INDEX(Tasks!$A:$A,ROW()-1)="","",IF(ISERROR(FIND(".",INDEX(Tasks!$A:$A,ROW()-1))),""," ")&INDEX(Tasks!$D:$D,ROW()-1)) -> Calibration: LiDAR - IMU | C9: =IF(INDEX(Tasks!$G:$G,ROW()-1)="","",INDEX(Tasks!$G:$G,ROW()-1)) -> TBD | D9: =IF(INDEX(Tasks!$H:$H,ROW()-1)="","",INDEX(Tasks!$H:$H,ROW()-1)) | E9: =IF(INDEX(Tasks!$I:$I,ROW()-1)="","",INDEX(Tasks!$I:$I,ROW()-1)) | F9: =IF(INDEX(Tasks!$K:$K,ROW()-1)="","",INDEX(Tasks!$K:$K,ROW()-1)) | BA9: Not Started
A10: =IF(INDEX(Tasks!$A:$A,ROW()-1)="","",INDEX(Tasks!$A:$A,ROW()-1)) -> TB-2.4 | B10: =IF(INDEX(Tasks!$A:$A,ROW()-1)="","",IF(ISERROR(FIND(".",INDEX(Tasks!$A:$A,ROW()-1))),""," ")&INDEX(Tasks!$D:$D,ROW()-1)) -> Calibration: RealSense - ZED | C10: =IF(INDEX(Tasks!$G:$G,ROW()-1)="","",INDEX(Tasks!$G:$G,ROW()-1)) -> TBD | D10: =IF(INDEX(Tasks!$H:$H,ROW()-1)="","",INDEX(Tasks!$H:$H,ROW()-1)) | E10: =IF(INDEX(Tasks!$I:$I,ROW()-1)="","",INDEX(Tasks!$I:$I,ROW()-1)) | F10: =IF(INDEX(Tasks!$K:$K,ROW()-1)="","",INDEX(Tasks!$K:$K,ROW()-1)) | BA10: Milestone
A11: =IF(INDEX(Tasks!$A:$A,ROW()-1)="","",INDEX(Tasks!$A:$A,ROW()-1)) -> TB-2.5 | B11: =IF(INDEX(Tasks!$A:$A,ROW()-1)="","",IF(ISERROR(FIND(".",INDEX(Tasks!$A:$A,ROW()-1))),""," ")&INDEX(Tasks!$D:$D,ROW()-1)) -> Calibration: ZED - Arducam | C11: =IF(INDEX(Tasks!$G:$G,ROW()-1)="","",INDEX(Tasks!$G:$G,ROW()-1)) -> TBD | D11: =IF(INDEX(Tasks!$H:$H,ROW()-1)="","",INDEX(Tasks!$H:$H,ROW()-1)) | E11: =IF(INDEX(Tasks!$I:$I,ROW()-1)="","",INDEX(Tasks!$I:$I,ROW()-1)) | F11: =IF(INDEX(Tasks!$K:$K,ROW()-1)="","",INDEX(Tasks!$K:$K,ROW()-1)) | BA11: Today's week
A12: =IF(INDEX(Tasks!$A:$A,ROW()-1)="","",INDEX(Tasks!$A:$A,ROW()-1)) -> TB-2.6 | B12: =IF(INDEX(Tasks!$A:$A,ROW()-1)="","",IF(ISERROR(FIND(".",INDEX(Tasks!$A:$A,ROW()-1))),""," ")&INDEX(Tasks!$D:$D,ROW()-1)) -> Calibration: Radars - ZED | C12: =IF(INDEX(Tasks!$G:$G,ROW()-1)="","",INDEX(Tasks!$G:$G,ROW()-1)) -> TBD | D12: =IF(INDEX(Tasks!$H:$H,ROW()-1)="","",INDEX(Tasks!$H:$H,ROW()-1)) | E12: =IF(INDEX(Tasks!$I:$I,ROW()-1)="","",INDEX(Tasks!$I:$I,ROW()-1)) | F12: =IF(INDEX(Tasks!$K:$K,ROW()-1)="","",INDEX(Tasks!$K:$K,ROW()-1))
A13: =IF(INDEX(Tasks!$A:$A,ROW()-1)="","",INDEX(Tasks!$A:$A,ROW()-1)) -> TB-3 | B13: =IF(INDEX(Tasks!$A:$A,ROW()-1)="","",IF(ISERROR(FIND(".",INDEX(Tasks!$A:$A,ROW()-1))),""," ")&INDEX(Tasks!$D:$D,ROW()-1)) -> Time sync & TF chain | C13: =IF(INDEX(Tasks!$G:$G,ROW()-1)="","",INDEX(Tasks!$G:$G,ROW()-1)) -> TBD | D13: =IF(INDEX(Tasks!$H:$H,ROW()-1)="","",INDEX(Tasks!$H:$H,ROW()-1)) -> In Progress | E13: =IF(INDEX(Tasks!$I:$I,ROW()-1)="","",INDEX(Tasks!$I:$I,ROW()-1)) -> 46202 | F13: =IF(INDEX(Tasks!$K:$K,ROW()-1)="","",INDEX(Tasks!$K:$K,ROW()-1)) -> 46206 | BA13: Red End date = overdue
A14: =IF(INDEX(Tasks!$A:$A,ROW()-1)="","",INDEX(Tasks!$A:$A,ROW()-1)) -> TB-4 | B14: =IF(INDEX(Tasks!$A:$A,ROW()-1)="","",IF(ISERROR(FIND(".",INDEX(Tasks!$A:$A,ROW()-1))),""," ")&INDEX(Tasks!$D:$D,ROW()-1)) -> Wi-Fi & comms logging | C14: =IF(INDEX(Tasks!$G:$G,ROW()-1)="","",INDEX(Tasks!$G:$G,ROW()-1)) -> TBD | D14: =IF(INDEX(Tasks!$H:$H,ROW()-1)="","",INDEX(Tasks!$H:$H,ROW()-1)) -> In Progress | E14: =IF(INDEX(Tasks!$I:$I,ROW()-1)="","",INDEX(Tasks!$I:$I,ROW()-1)) -> 46307 | F14: =IF(INDEX(Tasks!$K:$K,ROW()-1)="","",INDEX(Tasks!$K:$K,ROW()-1)) -> 46318
A15: =IF(INDEX(Tasks!$A:$A,ROW()-1)="","",INDEX(Tasks!$A:$A,ROW()-1)) -> TB-5 | B15: =IF(INDEX(Tasks!$A:$A,ROW()-1)="","",IF(ISERROR(FIND(".",INDEX(Tasks!$A:$A,ROW()-1))),""," ")&INDEX(Tasks!$D:$D,ROW()-1)) -> Recording tooling fixes | C15: =IF(INDEX(Tasks!$G:$G,ROW()-1)="","",INDEX(Tasks!$G:$G,ROW()-1)) -> TBD | D15: =IF(INDEX(Tasks!$H:$H,ROW()-1)="","",INDEX(Tasks!$H:$H,ROW()-1)) -> Not Started | E15: =IF(INDEX(Tasks!$I:$I,ROW()-1)="","",INDEX(Tasks!$I:$I,ROW()-1)) -> 46307 | F15: =IF(INDEX(Tasks!$K:$K,ROW()-1)="","",INDEX(Tasks!$K:$K,ROW()-1)) -> 46318
A16: =IF(INDEX(Tasks!$A:$A,ROW()-1)="","",INDEX(Tasks!$A:$A,ROW()-1)) -> G2-DS-1 | B16: =IF(INDEX(Tasks!$A:$A,ROW()-1)="","",IF(ISERROR(FIND(".",INDEX(Tasks!$A:$A,ROW()-1))),""," ")&INDEX(Tasks!$D:$D,ROW()-1)) -> Recording campaign | C16: =IF(INDEX(Tasks!$G:$G,ROW()-1)="","",INDEX(Tasks!$G:$G,ROW()-1)) -> TBD | D16: =IF(INDEX(Tasks!$H:$H,ROW()-1)="","",INDEX(Tasks!$H:$H,ROW()-1)) -> Partially Completed | E16: =IF(INDEX(Tasks!$I:$I,ROW()-1)="","",INDEX(Tasks!$I:$I,ROW()-1)) -> 46314 | F16: =IF(INDEX(Tasks!$K:$K,ROW()-1)="","",INDEX(Tasks!$K:$K,ROW()-1)) -> 46353
A17: =IF(INDEX(Tasks!$A:$A,ROW()-1)="","",INDEX(Tasks!$A:$A,ROW()-1)) -> G2-DS-1.1 | B17: =IF(INDEX(Tasks!$A:$A,ROW()-1)="","",IF(ISERROR(FIND(".",INDEX(Tasks!$A:$A,ROW()-1))),""," ")&INDEX(Tasks!$D:$D,ROW()-1)) -> Indoor Trajectory Sessions | C17: =IF(INDEX(Tasks!$G:$G,ROW()-1)="","",INDEX(Tasks!$G:$G,ROW()-1)) -> TBD | D17: =IF(INDEX(Tasks!$H:$H,ROW()-1)="","",INDEX(Tasks!$H:$H,ROW()-1)) -> Partially Completed | E17: =IF(INDEX(Tasks!$I:$I,ROW()-1)="","",INDEX(Tasks!$I:$I,ROW()-1)) -> 46202 | F17: =IF(INDEX(Tasks!$K:$K,ROW()-1)="","",INDEX(Tasks!$K:$K,ROW()-1)) -> 46206
A18: =IF(INDEX(Tasks!$A:$A,ROW()-1)="","",INDEX(Tasks!$A:$A,ROW()-1)) -> G2-DS-1.2 | B18: =IF(INDEX(Tasks!$A:$A,ROW()-1)="","",IF(ISERROR(FIND(".",INDEX(Tasks!$A:$A,ROW()-1))),""," ")&INDEX(Tasks!$D:$D,ROW()-1)) -> Outdoor Trajectory Sessions | C18: =IF(INDEX(Tasks!$G:$G,ROW()-1)="","",INDEX(Tasks!$G:$G,ROW()-1)) -> TBD | D18: =IF(INDEX(Tasks!$H:$H,ROW()-1)="","",INDEX(Tasks!$H:$H,ROW()-1)) -> Not Started | E18: =IF(INDEX(Tasks!$I:$I,ROW()-1)="","",INDEX(Tasks!$I:$I,ROW()-1)) | F18: =IF(INDEX(Tasks!$K:$K,ROW()-1)="","",INDEX(Tasks!$K:$K,ROW()-1))
A19: =IF(INDEX(Tasks!$A:$A,ROW()-1)="","",INDEX(Tasks!$A:$A,ROW()-1)) -> G2-DS-1.3 | B19: =IF(INDEX(Tasks!$A:$A,ROW()-1)="","",IF(ISERROR(FIND(".",INDEX(Tasks!$A:$A,ROW()-1))),""," ")&INDEX(Tasks!$D:$D,ROW()-1)) -> Record sites 2 and 3 | C19: =IF(INDEX(Tasks!$G:$G,ROW()-1)="","",INDEX(Tasks!$G:$G,ROW()-1)) -> TBD | D19: =IF(INDEX(Tasks!$H:$H,ROW()-1)="","",INDEX(Tasks!$H:$H,ROW()-1)) -> Not Started | E19: =IF(INDEX(Tasks!$I:$I,ROW()-1)="","",INDEX(Tasks!$I:$I,ROW()-1)) -> 46321 | F19: =IF(INDEX(Tasks!$K:$K,ROW()-1)="","",INDEX(Tasks!$K:$K,ROW()-1)) -> 46346
A20: =IF(INDEX(Tasks!$A:$A,ROW()-1)="","",INDEX(Tasks!$A:$A,ROW()-1)) -> G2-DS-1.4 | B20: =IF(INDEX(Tasks!$A:$A,ROW()-1)="","",IF(ISERROR(FIND(".",INDEX(Tasks!$A:$A,ROW()-1))),""," ")&INDEX(Tasks!$D:$D,ROW()-1)) -> Calibration rosbag | C20: =IF(INDEX(Tasks!$G:$G,ROW()-1)="","",INDEX(Tasks!$G:$G,ROW()-1)) -> TBD | D20: =IF(INDEX(Tasks!$H:$H,ROW()-1)="","",INDEX(Tasks!$H:$H,ROW()-1)) | E20: =IF(INDEX(Tasks!$I:$I,ROW()-1)="","",INDEX(Tasks!$I:$I,ROW()-1)) -> 46314 | F20: =IF(INDEX(Tasks!$K:$K,ROW()-1)="","",INDEX(Tasks!$K:$K,ROW()-1)) -> 46318
A21: =IF(INDEX(Tasks!$A:$A,ROW()-1)="","",INDEX(Tasks!$A:$A,ROW()-1)) -> G2-DS-1.5 | B21: =IF(INDEX(Tasks!$A:$A,ROW()-1)="","",IF(ISERROR(FIND(".",INDEX(Tasks!$A:$A,ROW()-1))),""," ")&INDEX(Tasks!$D:$D,ROW()-1)) -> Short test recordings | C21: =IF(INDEX(Tasks!$G:$G,ROW()-1)="","",INDEX(Tasks!$G:$G,ROW()-1)) -> TBD | D21: =IF(INDEX(Tasks!$H:$H,ROW()-1)="","",INDEX(Tasks!$H:$H,ROW()-1)) | E21: =IF(INDEX(Tasks!$I:$I,ROW()-1)="","",INDEX(Tasks!$I:$I,ROW()-1)) -> 46314 | F21: =IF(INDEX(Tasks!$K:$K,ROW()-1)="","",INDEX(Tasks!$K:$K,ROW()-1)) -> 46318
A22: =IF(INDEX(Tasks!$A:$A,ROW()-1)="","",INDEX(Tasks!$A:$A,ROW()-1)) -> G2-DS-2 | B22: =IF(INDEX(Tasks!$A:$A,ROW()-1)="","",IF(ISERROR(FIND(".",INDEX(Tasks!$A:$A,ROW()-1))),""," ")&INDEX(Tasks!$D:$D,ROW()-1)) -> Per-pass processing | C22: =IF(INDEX(Tasks!$G:$G,ROW()-1)="","",INDEX(Tasks!$G:$G,ROW()-1)) -> TBD | D22: =IF(INDEX(Tasks!$H:$H,ROW()-1)="","",INDEX(Tasks!$H:$H,ROW()-1)) -> In Progress | E22: =IF(INDEX(Tasks!$I:$I,ROW()-1)="","",INDEX(Tasks!$I:$I,ROW()-1)) -> 46307 | F22: =IF(INDEX(Tasks!$K:$K,ROW()-1)="","",INDEX(Tasks!$K:$K,ROW()-1)) -> 46374
A23: =IF(INDEX(Tasks!$A:$A,ROW()-1)="","",INDEX(Tasks!$A:$A,ROW()-1)) -> G2-DS-2.1 | B23: =IF(INDEX(Tasks!$A:$A,ROW()-1)="","",IF(ISERROR(FIND(".",INDEX(Tasks!$A:$A,ROW()-1))),""," ")&INDEX(Tasks!$D:$D,ROW()-1)) -> Merging Sensor Data | C23: =IF(INDEX(Tasks!$G:$G,ROW()-1)="","",INDEX(Tasks!$G:$G,ROW()-1)) -> TBD | D23: =IF(INDEX(Tasks!$H:$H,ROW()-1)="","",INDEX(Tasks!$H:$H,ROW()-1)) -> In Progress | E23: =IF(INDEX(Tasks!$I:$I,ROW()-1)="","",INDEX(Tasks!$I:$I,ROW()-1)) -> 46202 | F23: =IF(INDEX(Tasks!$K:$K,ROW()-1)="","",INDEX(Tasks!$K:$K,ROW()-1)) -> 46206
A24: =IF(INDEX(Tasks!$A:$A,ROW()-1)="","",INDEX(Tasks!$A:$A,ROW()-1)) -> G2-DS-2.2 | B24: =IF(INDEX(Tasks!$A:$A,ROW()-1)="","",IF(ISERROR(FIND(".",INDEX(Tasks!$A:$A,ROW()-1))),""," ")&INDEX(Tasks!$D:$D,ROW()-1)) -> Timestamp Alignment Post-Processing | C24: =IF(INDEX(Tasks!$G:$G,ROW()-1)="","",INDEX(Tasks!$G:$G,ROW()-1)) -> TBD | D24: =IF(INDEX(Tasks!$H:$H,ROW()-1)="","",INDEX(Tasks!$H:$H,ROW()-1)) -> Not Started | E24: =IF(INDEX(Tasks!$I:$I,ROW()-1)="","",INDEX(Tasks!$I:$I,ROW()-1)) -> 46202 | F24: =IF(INDEX(Tasks!$K:$K,ROW()-1)="","",INDEX(Tasks!$K:$K,ROW()-1)) -> 46206
A25: =IF(INDEX(Tasks!$A:$A,ROW()-1)="","",INDEX(Tasks!$A:$A,ROW()-1)) -> G2-DS-3 | B25: =IF(INDEX(Tasks!$A:$A,ROW()-1)="","",IF(ISERROR(FIND(".",INDEX(Tasks!$A:$A,ROW()-1))),""," ")&INDEX(Tasks!$D:$D,ROW()-1)) -> Reference maps & board networks per site | C25: =IF(INDEX(Tasks!$G:$G,ROW()-1)="","",INDEX(Tasks!$G:$G,ROW()-1)) -> TBD | D25: =IF(INDEX(Tasks!$H:$H,ROW()-1)="","",INDEX(Tasks!$H:$H,ROW()-1)) -> In Progress | E25: =IF(INDEX(Tasks!$I:$I,ROW()-1)="","",INDEX(Tasks!$I:$I,ROW()-1)) -> 46307 | F25: =IF(INDEX(Tasks!$K:$K,ROW()-1)="","",INDEX(Tasks!$K:$K,ROW()-1)) -> 46360
... A404: =IF(INDEX(Tasks!$A:$A,ROW()-1)="","",INDEX(Tasks!$A:$A,ROW()-1)) | B404: =IF(INDEX(Tasks!$A:$A,ROW()-1)="","",IF(ISERROR(FIND(".",INDEX(Tasks!$A:$A,ROW()-1))),""," ")&INDEX(Tasks!$D:$D,ROW()-1)) | C404: =IF(INDEX(Tasks!$G:$G,ROW()-1)="","",INDEX(Tasks!$G:$G,ROW()-1)) | D404: =IF(INDEX(Tasks!$H:$H,ROW()-1)="","",INDEX(Tasks!$H:$H,ROW()-1)) | E404: =IF(INDEX(Tasks!$I:$I,ROW()-1)="","",INDEX(Tasks!$I:$I,ROW()-1)) | F404: =IF(INDEX(Tasks!$K:$K,ROW()-1)="","",INDEX(Tasks!$K:$K,ROW()-1))

Sheet Problems
A1: Problems
A2: Log anything that blocks work for more than a day. Link the task it blocks. | E2: Date opened for seeded rows = when they were logged here (7 Oct 2026); found in the SCooP code/paper and this project's work.
A3: P-ID | B3: Opened | C3: Goal | D3: Task ID | E3: Owner (role) | F3: Severity | G3: Status | H3: What happened | I3: Blocks / impact | J3: Root cause | K3: Fix / workaround | L3: Closed | M3: Notes
A4: P-001 | B4: 46302 | C4: G2 SCooP dataset & paper | D4: G2-DS-4 | E4: SCooP dataset | F4: Major | G4: Investigating | H4: coop_2: mobile_2's on-board VSLAM was not recorded; its camera has dropouts. | I4: mobile_2 reference track for coop_2 | J4: On-board VSLAM topic not in the recording | K4: Offline cuVSLAM + depth tracking/PGO with board and LiDAR fixes; stages 05/07/08 off, boards and Arducam borrowed from survey_1
A5: P-002 | B5: 46302 | C5: Shared SCooP testbed | D5: TB-5 | E5: Sensors & platform | F5: Major | G5: Open | H5: Survey mode: mobile_2 parked; its depth, IMU and IR not recorded, no trajectory. | I5: mobile_2 data in survey passes | J5: record.yaml survey profile | K5: Add the topics to the survey profile (TB-5)
A6: P-003 | B6: 46302 | C6: G2 SCooP dataset & paper | D6: G2-DS-4 | E6: SCooP dataset | F6: Major | G6: Investigating | H6: ZED's own tracking drifts; infra-camera ChArUco extrinsics in map_zed carry that drift. | I6: Infra camera placement; map_zed | J6: ZED odometry not trusted | K6: map_zed placed at mobile_1's start, odom_zed dropped
A7: P-004 | B7: 46302 | C7: Shared SCooP testbed | D7: TB-3 | E7: Sensors & platform | F7: Major | G7: Open | H7: Sniffer NTP asymmetry bias (up to 7.8 ms) not measured; NTP numbers from one pass only. | I7: Clock table in the paper; CSI timing
A8: P-005 | B8: 46302 | C8: G2 SCooP dataset & paper | D8: G2-DS-3 | E8: SCooP dataset | F8: Minor | G8: Open | H8: Seq B walls thicker than seq A (single-visit corridors). | I8: Map quality numbers | J8: Corridors visited once
A9: P-006 | B9: 46302 | C9: Shared SCooP testbed | D9: TB-1 | E9: Sensors & platform | F9: Minor | G9: Open | H9: Cascade radar spec and mobile_2 radar/Wi-Fi parts unconfirmed. | I9: Paper sensors table
A10: P-007 | B10: 46302 | C10: G2 SCooP dataset & paper | D10: G2-DS-7 | E10: SCooP dataset | F10: Minor | G10: Open | H10: CSI resolves relative speeds only up to about 1.2 m/s. | I10: Channel analysis at higher speeds | J10: CSI sample rate | K10: State as a limitation
A11: P-008 | B11: 46302 | C11: G2 SCooP dataset & paper | D11: G2-BP-A | E11: SCooP dataset | F11: Minor | G11: Open | H11: RESULTS_PLAN.md cites old stage paths (03_anchor, 08_reference_traj -> now 05_anchor, 04_reference_traj). | I11: Following the results plan | J11: Stages renumbered | K11: Update the paths
A12: P-009 | B12: 46302 | C12: G1 ED305 live digital twin | D12: G1-SP-3 | E12: Sensors & platform | F12: Blocker | G12: Open | H12: No access to the HCIS-Lab/ED305-cameras repo (calibration files). | I12: Camera calibration -> coverage -> placement | J12: Repo not shared with the GitHub app | K12: Share the calibration/ files or grant repo access
A13: P-010 | B13: 46302 | C13: G1 ED305 live digital twin | D13: G1-SP-4 | E13: Sensors & platform | F13: Major | G13: Investigating | H13: Each camera mount's range of movement is unknown. | I13: Camera placement optimization | J13: Not documented | K13: Assumed ranges for now; measure from video (measure_rotation.py) or fit printed pan-tilt heads

Sheet Interfaces
A1: Interfaces
A2: One row per hand-off between owners (arrows in the system diagram). Fill format/rate/frame when agreed.
A3: I-ID | B3: From (component) | C3: To (component) | D3: What is passed | E3: Topic / format | F3: Rate | G3: Frame & timestamps | H3: From owner | I3: To owner | J3: State | K3: Notes
A4: I-01 | B4: Sensors | C4: Odometry | D4: RGB-D, IMU, wheel ticks | E4: TBD | F4: TBD | G4: TBD | H4: Sensors & platform | I4: Sensors & platform | J4: Not defined
A5: I-02 | B5: Odometry | C5: Metric prior / Tracking | D5: Pose prior T_k with covariance | E5: TBD | F5: TBD | G5: TBD | H5: Sensors & platform | I5: GS-SLAM | J5: Not defined
A6: I-03 | B6: Sensors | C6: Metric prior | D6: Depth image + intrinsics K | E6: TBD | F6: TBD | G6: TBD | H6: Sensors & platform | I6: GS-SLAM | J6: Not defined
A7: I-04 | B7: Mobile robots (sensor rig) | C7: GS-SLAM front end | D7: Current frame: colour I_k, depth D_k | E7: TBD | F7: TBD | G7: TBD | H7: Sensors & platform | I7: GS-SLAM | J7: Not defined
A8: I-05 | B8: GS-SLAM tracking | C8: Isaac Sim robot prims | D8: Each robot's pose T_k (every frame) | E8: TBD | F8: TBD | G8: TBD | H8: GS-SLAM | I8: Isaac Sim | J8: Not defined
A9: I-06 | B9: GS-SLAM back end | C9: Map fusion | D9: Submaps / keyframes per robot | E9: TBD | F9: TBD | G9: TBD | H9: GS-SLAM | I9: GS-SLAM | J9: Not defined
A10: I-07 | B10: Map fusion | C10: Scene update (object retrieval) | D10: Global map G* | E10: TBD | F10: TBD | G10: TBD | H10: GS-SLAM | I10: Scene detection | J10: Not defined
A11: I-08 | B11: Isaac Sim | C11: Scene update (change detection) | D11: Expected view (render of the twin) | E11: TBD | F11: TBD | G11: TBD | H11: Isaac Sim | I11: Scene detection | J11: Not defined
A12: I-09 | B12: Scene update (maintenance) | C12: Isaac Sim USD stage | D12: USD edits: add, move, remove | E12: TBD | F12: TBD | G12: TBD | H12: Scene detection | I12: Isaac Sim | J12: Not defined
A13: I-10 | B13: Isaac Sim | C13: Mobile robots | D13: Control commands | E13: TBD | F13: TBD | G13: TBD | H13: Isaac Sim | I13: Sensors & platform | J13: Not defined
A14: I-11 | B14: Isaac Sim | C14: Sionna RT | D14: Meshes, materials, all Tx/Rx poses | E14: TBD | F14: TBD | G14: TBD | H14: Isaac Sim | I14: Sionna RT | J14: Not defined
A15: I-12 | B15: ED305 cameras | C15: Scene update | D15: Live target positions (people, robots) in the room frame | E15: TBD | F15: TBD | G15: TBD | H15: Sensors & platform | I15: Scene detection | J15: Not defined
... A17: I-14 | B17: SCooP testbed logs | C17: Sionna RT validation | D17: Measured CSI / RSSI per link | E17: TBD | F17: TBD | G17: TBD | H17: SCooP dataset | I17: Sionna RT | J17: Not defined

Sheet Weekly Log
A1: Weekly Log
A2: Every Friday, one row per person. Blockers = problem IDs from Problems. Row 4 is an example: overwrite it.
A3: Week (Monday) | B3: Person | C3: Done | D3: Next | E3: Blockers (P-IDs) | F3: Notes
A4: 46300 | B4: (example) | C4: Coverage + placement tools; printed pan-tilt head design | D4: Get ED305 calibration files; print one head | E4: P-009 | F4: Example row

Sheet Runs
A1: Runs
A2: One row per pipeline run on the server. The server keeps the logs/bags; this sheet points to them. Row 4 is an example.
A3: Run ID | B3: Date | C3: Goal | D3: Task ID | E3: Data (pass / bag) | F3: Git commit | G3: Components | H3: Key numbers | I3: Result / notes | J3: Log location
A4: (example) R-0001 | B4: 46301 | C4: G2 SCooP dataset & paper | D4: G2-DS-4 | E4: 20260924/coop_2 | F4: (commit) | G4: map stages 03-04 | H4: mobile_2 track: board residual ... cm | I4: Track fixed except camera dropouts | J4: server:/data/processed/20260924/coop_2

Sheet Lists
A1: Lists
A2: Owner names and dropdown values.
A3: Role | B3: Person | C3: Owns | E3: Status | F3: Goal | G3: Severity | H3: Problem status | I3: Interface state
A4: Sensors & platform | B4: TBD | C4: Robots, sensors, odometry, calibration, time sync, ED305 cameras, SCooP testbed | E4: Not Started | F4: G1 ED305 live digital twin | G4: Blocker | H4: Open | I4: Not defined
A5: GS-SLAM | B5: TBD | C5: Metric prior, GS-SLAM front/back end, map fusion | E5: In Progress | F5: G2 SCooP dataset & paper | G5: Major | H5: Investigating | I5: Defined
A6: Scene detection | B6: TBD | C6: Scene update: asset library, retrieval, decomposition, change detection, maintenance | E6: Blocked | F6: Shared SCooP testbed | G6: Minor | H6: Resolved | I6: Implemented
A7: Isaac Sim | B7: TBD | C7: USD stage, robot prims, Gaussian/mesh layers, live edits, control, Sionna export | E7: Complete | F7: Dual-Link Communication | H7: Won't fix | I7: Tested
A8: Sionna RT | B8: TBD | C8: Scene export, path solver, channel output | E8: Partially Completed | F8: Semantic Communication
A9: SCooP dataset | B9: TBD | C9: SCooP recording campaign, reference poses, annotations, release, paper
A10: Dual-link comms | B10: TBD | C10: Dual-link communication workstream
A11: Semantic comms | B11: TBD | C11: Semantic communication workstream
A12: All (integration) | B12: TBD | C12: Cross-owner integration milestones
